2018-10-29 10:54:53,926 - da-service - INFO - hello log
2018-10-29 11:23:08,335 - da-service - WARNING - 访问了未知路径: [error: 404 Not Found: The requested URL was not found on the server.  If you entered the URL manually please check your spelling and try again.]
Traceback (most recent call last):
  File "C:\ProgramData\Anaconda3\envs\BI-dashboard\lib\site-packages\flask\app.py", line 1813, in full_dispatch_request
    rv = self.dispatch_request()
  File "C:\ProgramData\Anaconda3\envs\BI-dashboard\lib\site-packages\flask\app.py", line 1791, in dispatch_request
    self.raise_routing_exception(req)
  File "C:\ProgramData\Anaconda3\envs\BI-dashboard\lib\site-packages\flask\app.py", line 1774, in raise_routing_exception
    raise request.routing_exception
  File "C:\ProgramData\Anaconda3\envs\BI-dashboard\lib\site-packages\flask\ctx.py", line 336, in match_request
    self.url_adapter.match(return_rule=True)
  File "C:\ProgramData\Anaconda3\envs\BI-dashboard\lib\site-packages\werkzeug\routing.py", line 1581, in match
    raise NotFound()
werkzeug.exceptions.NotFound: 404 Not Found: The requested URL was not found on the server.  If you entered the URL manually please check your spelling and try again.
2018-10-29 11:23:22,665 - da-service - WARNING - 访问了未知路径: [error: 404 Not Found: The requested URL was not found on the server.  If you entered the URL manually please check your spelling and try again.]
Traceback (most recent call last):
  File "C:\ProgramData\Anaconda3\envs\BI-dashboard\lib\site-packages\flask\app.py", line 1813, in full_dispatch_request
    rv = self.dispatch_request()
  File "C:\ProgramData\Anaconda3\envs\BI-dashboard\lib\site-packages\flask\app.py", line 1791, in dispatch_request
    self.raise_routing_exception(req)
  File "C:\ProgramData\Anaconda3\envs\BI-dashboard\lib\site-packages\flask\app.py", line 1774, in raise_routing_exception
    raise request.routing_exception
  File "C:\ProgramData\Anaconda3\envs\BI-dashboard\lib\site-packages\flask\ctx.py", line 336, in match_request
    self.url_adapter.match(return_rule=True)
  File "C:\ProgramData\Anaconda3\envs\BI-dashboard\lib\site-packages\werkzeug\routing.py", line 1581, in match
    raise NotFound()
werkzeug.exceptions.NotFound: 404 Not Found: The requested URL was not found on the server.  If you entered the URL manually please check your spelling and try again.
2018-10-29 11:23:23,608 - da-service - WARNING - 访问了未知路径: [error: 404 Not Found: The requested URL was not found on the server.  If you entered the URL manually please check your spelling and try again.]
Traceback (most recent call last):
  File "C:\ProgramData\Anaconda3\envs\BI-dashboard\lib\site-packages\flask\app.py", line 1813, in full_dispatch_request
    rv = self.dispatch_request()
  File "C:\ProgramData\Anaconda3\envs\BI-dashboard\lib\site-packages\flask\app.py", line 1791, in dispatch_request
    self.raise_routing_exception(req)
  File "C:\ProgramData\Anaconda3\envs\BI-dashboard\lib\site-packages\flask\app.py", line 1774, in raise_routing_exception
    raise request.routing_exception
  File "C:\ProgramData\Anaconda3\envs\BI-dashboard\lib\site-packages\flask\ctx.py", line 336, in match_request
    self.url_adapter.match(return_rule=True)
  File "C:\ProgramData\Anaconda3\envs\BI-dashboard\lib\site-packages\werkzeug\routing.py", line 1581, in match
    raise NotFound()
werkzeug.exceptions.NotFound: 404 Not Found: The requested URL was not found on the server.  If you entered the URL manually please check your spelling and try again.
2018-10-29 11:23:23,852 - da-service - WARNING - 访问了未知路径: [error: 404 Not Found: The requested URL was not found on the server.  If you entered the URL manually please check your spelling and try again.]
Traceback (most recent call last):
  File "C:\ProgramData\Anaconda3\envs\BI-dashboard\lib\site-packages\flask\app.py", line 1813, in full_dispatch_request
    rv = self.dispatch_request()
  File "C:\ProgramData\Anaconda3\envs\BI-dashboard\lib\site-packages\flask\app.py", line 1791, in dispatch_request
    self.raise_routing_exception(req)
  File "C:\ProgramData\Anaconda3\envs\BI-dashboard\lib\site-packages\flask\app.py", line 1774, in raise_routing_exception
    raise request.routing_exception
  File "C:\ProgramData\Anaconda3\envs\BI-dashboard\lib\site-packages\flask\ctx.py", line 336, in match_request
    self.url_adapter.match(return_rule=True)
  File "C:\ProgramData\Anaconda3\envs\BI-dashboard\lib\site-packages\werkzeug\routing.py", line 1581, in match
    raise NotFound()
werkzeug.exceptions.NotFound: 404 Not Found: The requested URL was not found on the server.  If you entered the URL manually please check your spelling and try again.
2018-10-29 11:24:15,374 - da-service - WARNING - 内部服务发生异常: [error: 'role_menu_path' is undefined]
Traceback (most recent call last):
  File "C:\ProgramData\Anaconda3\envs\BI-dashboard\lib\site-packages\flask\app.py", line 2292, in wsgi_app
    response = self.full_dispatch_request()
  File "C:\ProgramData\Anaconda3\envs\BI-dashboard\lib\site-packages\flask\app.py", line 1815, in full_dispatch_request
    rv = self.handle_user_exception(e)
  File "C:\ProgramData\Anaconda3\envs\BI-dashboard\lib\site-packages\flask_restplus\api.py", line 557, in error_router
    return original_handler(e)
  File "C:\ProgramData\Anaconda3\envs\BI-dashboard\lib\site-packages\flask\app.py", line 1718, in handle_user_exception
    reraise(exc_type, exc_value, tb)
  File "C:\ProgramData\Anaconda3\envs\BI-dashboard\lib\site-packages\flask\_compat.py", line 35, in reraise
    raise value
  File "C:\ProgramData\Anaconda3\envs\BI-dashboard\lib\site-packages\flask\app.py", line 1813, in full_dispatch_request
    rv = self.dispatch_request()
  File "C:\ProgramData\Anaconda3\envs\BI-dashboard\lib\site-packages\flask\app.py", line 1799, in dispatch_request
    return self.view_functions[rule.endpoint](**req.view_args)
  File "F:\da-dashboard\server\route\route.py", line 25, in home_func
  File "C:\ProgramData\Anaconda3\envs\BI-dashboard\lib\site-packages\flask\templating.py", line 135, in render_template
    context, ctx.app)
  File "C:\ProgramData\Anaconda3\envs\BI-dashboard\lib\site-packages\flask\templating.py", line 117, in _render
    rv = template.render(context)
  File "C:\ProgramData\Anaconda3\envs\BI-dashboard\lib\site-packages\jinja2\asyncsupport.py", line 76, in render
    return original_render(self, *args, **kwargs)
  File "C:\ProgramData\Anaconda3\envs\BI-dashboard\lib\site-packages\jinja2\environment.py", line 1008, in render
    return self.environment.handle_exception(exc_info, True)
  File "C:\ProgramData\Anaconda3\envs\BI-dashboard\lib\site-packages\jinja2\environment.py", line 780, in handle_exception
    reraise(exc_type, exc_value, tb)
  File "C:\ProgramData\Anaconda3\envs\BI-dashboard\lib\site-packages\jinja2\_compat.py", line 37, in reraise
    raise value.with_traceback(tb)
  File "F:\da-dashboard\server\templates\admin\home.html", line 16, in top-level template code
    {% include '/menu/menu.html' %}
  File "F:\da-dashboard\server\templates\menu\menu.html", line 17, in top-level template code
    {% for menu_name, path_dict in role_menu_path.items() %}
  File "C:\ProgramData\Anaconda3\envs\BI-dashboard\lib\site-packages\jinja2\environment.py", line 430, in getattr
    return getattr(obj, attribute)
jinja2.exceptions.UndefinedError: 'role_menu_path' is undefined
2018-10-29 11:24:16,073 - da-service - WARNING - 访问了未知路径: [error: 404 Not Found: The requested URL was not found on the server.  If you entered the URL manually please check your spelling and try again.]
Traceback (most recent call last):
  File "C:\ProgramData\Anaconda3\envs\BI-dashboard\lib\site-packages\flask\app.py", line 1813, in full_dispatch_request
    rv = self.dispatch_request()
  File "C:\ProgramData\Anaconda3\envs\BI-dashboard\lib\site-packages\flask\app.py", line 1791, in dispatch_request
    self.raise_routing_exception(req)
  File "C:\ProgramData\Anaconda3\envs\BI-dashboard\lib\site-packages\flask\app.py", line 1774, in raise_routing_exception
    raise request.routing_exception
  File "C:\ProgramData\Anaconda3\envs\BI-dashboard\lib\site-packages\flask\ctx.py", line 336, in match_request
    self.url_adapter.match(return_rule=True)
  File "C:\ProgramData\Anaconda3\envs\BI-dashboard\lib\site-packages\werkzeug\routing.py", line 1581, in match
    raise NotFound()
werkzeug.exceptions.NotFound: 404 Not Found: The requested URL was not found on the server.  If you entered the URL manually please check your spelling and try again.
2018-10-29 11:25:11,686 - da-service - WARNING - 访问了未知路径: [error: 404 Not Found: The requested URL was not found on the server.  If you entered the URL manually please check your spelling and try again.]
Traceback (most recent call last):
  File "C:\ProgramData\Anaconda3\envs\BI-dashboard\lib\site-packages\flask\app.py", line 1813, in full_dispatch_request
    rv = self.dispatch_request()
  File "C:\ProgramData\Anaconda3\envs\BI-dashboard\lib\site-packages\flask\app.py", line 1791, in dispatch_request
    self.raise_routing_exception(req)
  File "C:\ProgramData\Anaconda3\envs\BI-dashboard\lib\site-packages\flask\app.py", line 1774, in raise_routing_exception
    raise request.routing_exception
  File "C:\ProgramData\Anaconda3\envs\BI-dashboard\lib\site-packages\flask\ctx.py", line 336, in match_request
    self.url_adapter.match(return_rule=True)
  File "C:\ProgramData\Anaconda3\envs\BI-dashboard\lib\site-packages\werkzeug\routing.py", line 1581, in match
    raise NotFound()
werkzeug.exceptions.NotFound: 404 Not Found: The requested URL was not found on the server.  If you entered the URL manually please check your spelling and try again.
2018-10-29 11:25:11,710 - da-service - WARNING - 访问了未知路径: [error: 404 Not Found: The requested URL was not found on the server.  If you entered the URL manually please check your spelling and try again.]
Traceback (most recent call last):
  File "C:\ProgramData\Anaconda3\envs\BI-dashboard\lib\site-packages\flask\app.py", line 1813, in full_dispatch_request
    rv = self.dispatch_request()
  File "C:\ProgramData\Anaconda3\envs\BI-dashboard\lib\site-packages\flask\app.py", line 1791, in dispatch_request
    self.raise_routing_exception(req)
  File "C:\ProgramData\Anaconda3\envs\BI-dashboard\lib\site-packages\flask\app.py", line 1774, in raise_routing_exception
    raise request.routing_exception
  File "C:\ProgramData\Anaconda3\envs\BI-dashboard\lib\site-packages\flask\ctx.py", line 336, in match_request
    self.url_adapter.match(return_rule=True)
  File "C:\ProgramData\Anaconda3\envs\BI-dashboard\lib\site-packages\werkzeug\routing.py", line 1581, in match
    raise NotFound()
werkzeug.exceptions.NotFound: 404 Not Found: The requested URL was not found on the server.  If you entered the URL manually please check your spelling and try again.
2018-10-29 11:25:12,500 - da-service - WARNING - 访问了未知路径: [error: 404 Not Found: The requested URL was not found on the server.  If you entered the URL manually please check your spelling and try again.]
Traceback (most recent call last):
  File "C:\ProgramData\Anaconda3\envs\BI-dashboard\lib\site-packages\flask\app.py", line 1813, in full_dispatch_request
    rv = self.dispatch_request()
  File "C:\ProgramData\Anaconda3\envs\BI-dashboard\lib\site-packages\flask\app.py", line 1791, in dispatch_request
    self.raise_routing_exception(req)
  File "C:\ProgramData\Anaconda3\envs\BI-dashboard\lib\site-packages\flask\app.py", line 1774, in raise_routing_exception
    raise request.routing_exception
  File "C:\ProgramData\Anaconda3\envs\BI-dashboard\lib\site-packages\flask\ctx.py", line 336, in match_request
    self.url_adapter.match(return_rule=True)
  File "C:\ProgramData\Anaconda3\envs\BI-dashboard\lib\site-packages\werkzeug\routing.py", line 1581, in match
    raise NotFound()
werkzeug.exceptions.NotFound: 404 Not Found: The requested URL was not found on the server.  If you entered the URL manually please check your spelling and try again.
2018-10-29 11:51:09,539 - da-service - WARNING - 访问了未知路径: [error: 404 Not Found: The requested URL was not found on the server.  If you entered the URL manually please check your spelling and try again.]
Traceback (most recent call last):
  File "C:\ProgramData\Anaconda3\envs\BI-dashboard\lib\site-packages\flask\app.py", line 1813, in full_dispatch_request
    rv = self.dispatch_request()
  File "C:\ProgramData\Anaconda3\envs\BI-dashboard\lib\site-packages\flask\app.py", line 1791, in dispatch_request
    self.raise_routing_exception(req)
  File "C:\ProgramData\Anaconda3\envs\BI-dashboard\lib\site-packages\flask\app.py", line 1774, in raise_routing_exception
    raise request.routing_exception
  File "C:\ProgramData\Anaconda3\envs\BI-dashboard\lib\site-packages\flask\ctx.py", line 336, in match_request
    self.url_adapter.match(return_rule=True)
  File "C:\ProgramData\Anaconda3\envs\BI-dashboard\lib\site-packages\werkzeug\routing.py", line 1581, in match
    raise NotFound()
werkzeug.exceptions.NotFound: 404 Not Found: The requested URL was not found on the server.  If you entered the URL manually please check your spelling and try again.
2018-10-29 11:51:13,703 - da-service - WARNING - 访问了未知路径: [error: 404 Not Found: The requested URL was not found on the server.  If you entered the URL manually please check your spelling and try again.]
Traceback (most recent call last):
  File "C:\ProgramData\Anaconda3\envs\BI-dashboard\lib\site-packages\flask\app.py", line 1813, in full_dispatch_request
    rv = self.dispatch_request()
  File "C:\ProgramData\Anaconda3\envs\BI-dashboard\lib\site-packages\flask\app.py", line 1791, in dispatch_request
    self.raise_routing_exception(req)
  File "C:\ProgramData\Anaconda3\envs\BI-dashboard\lib\site-packages\flask\app.py", line 1774, in raise_routing_exception
    raise request.routing_exception
  File "C:\ProgramData\Anaconda3\envs\BI-dashboard\lib\site-packages\flask\ctx.py", line 336, in match_request
    self.url_adapter.match(return_rule=True)
  File "C:\ProgramData\Anaconda3\envs\BI-dashboard\lib\site-packages\werkzeug\routing.py", line 1581, in match
    raise NotFound()
werkzeug.exceptions.NotFound: 404 Not Found: The requested URL was not found on the server.  If you entered the URL manually please check your spelling and try again.
2018-10-29 11:51:15,871 - da-service - WARNING - 访问了未知路径: [error: 404 Not Found: The requested URL was not found on the server.  If you entered the URL manually please check your spelling and try again.]
Traceback (most recent call last):
  File "C:\ProgramData\Anaconda3\envs\BI-dashboard\lib\site-packages\flask\app.py", line 1813, in full_dispatch_request
    rv = self.dispatch_request()
  File "C:\ProgramData\Anaconda3\envs\BI-dashboard\lib\site-packages\flask\app.py", line 1791, in dispatch_request
    self.raise_routing_exception(req)
  File "C:\ProgramData\Anaconda3\envs\BI-dashboard\lib\site-packages\flask\app.py", line 1774, in raise_routing_exception
    raise request.routing_exception
  File "C:\ProgramData\Anaconda3\envs\BI-dashboard\lib\site-packages\flask\ctx.py", line 336, in match_request
    self.url_adapter.match(return_rule=True)
  File "C:\ProgramData\Anaconda3\envs\BI-dashboard\lib\site-packages\werkzeug\routing.py", line 1581, in match
    raise NotFound()
werkzeug.exceptions.NotFound: 404 Not Found: The requested URL was not found on the server.  If you entered the URL manually please check your spelling and try again.
2018-10-29 11:51:28,421 - da-service - WARNING - 访问了未知路径: [error: 404 Not Found: The requested URL was not found on the server.  If you entered the URL manually please check your spelling and try again.]
Traceback (most recent call last):
  File "C:\ProgramData\Anaconda3\envs\BI-dashboard\lib\site-packages\flask\app.py", line 1813, in full_dispatch_request
    rv = self.dispatch_request()
  File "C:\ProgramData\Anaconda3\envs\BI-dashboard\lib\site-packages\flask\app.py", line 1791, in dispatch_request
    self.raise_routing_exception(req)
  File "C:\ProgramData\Anaconda3\envs\BI-dashboard\lib\site-packages\flask\app.py", line 1774, in raise_routing_exception
    raise request.routing_exception
  File "C:\ProgramData\Anaconda3\envs\BI-dashboard\lib\site-packages\flask\ctx.py", line 336, in match_request
    self.url_adapter.match(return_rule=True)
  File "C:\ProgramData\Anaconda3\envs\BI-dashboard\lib\site-packages\werkzeug\routing.py", line 1581, in match
    raise NotFound()
werkzeug.exceptions.NotFound: 404 Not Found: The requested URL was not found on the server.  If you entered the URL manually please check your spelling and try again.
2018-10-29 11:51:28,428 - da-service - WARNING - 访问了未知路径: [error: 404 Not Found: The requested URL was not found on the server.  If you entered the URL manually please check your spelling and try again.]
Traceback (most recent call last):
  File "C:\ProgramData\Anaconda3\envs\BI-dashboard\lib\site-packages\flask\app.py", line 1813, in full_dispatch_request
    rv = self.dispatch_request()
  File "C:\ProgramData\Anaconda3\envs\BI-dashboard\lib\site-packages\flask\app.py", line 1791, in dispatch_request
    self.raise_routing_exception(req)
  File "C:\ProgramData\Anaconda3\envs\BI-dashboard\lib\site-packages\flask\app.py", line 1774, in raise_routing_exception
    raise request.routing_exception
  File "C:\ProgramData\Anaconda3\envs\BI-dashboard\lib\site-packages\flask\ctx.py", line 336, in match_request
    self.url_adapter.match(return_rule=True)
  File "C:\ProgramData\Anaconda3\envs\BI-dashboard\lib\site-packages\werkzeug\routing.py", line 1581, in match
    raise NotFound()
werkzeug.exceptions.NotFound: 404 Not Found: The requested URL was not found on the server.  If you entered the URL manually please check your spelling and try again.
2018-10-29 11:51:28,894 - da-service - WARNING - 访问了未知路径: [error: 404 Not Found: The requested URL was not found on the server.  If you entered the URL manually please check your spelling and try again.]
Traceback (most recent call last):
  File "C:\ProgramData\Anaconda3\envs\BI-dashboard\lib\site-packages\flask\app.py", line 1813, in full_dispatch_request
    rv = self.dispatch_request()
  File "C:\ProgramData\Anaconda3\envs\BI-dashboard\lib\site-packages\flask\app.py", line 1791, in dispatch_request
    self.raise_routing_exception(req)
  File "C:\ProgramData\Anaconda3\envs\BI-dashboard\lib\site-packages\flask\app.py", line 1774, in raise_routing_exception
    raise request.routing_exception
  File "C:\ProgramData\Anaconda3\envs\BI-dashboard\lib\site-packages\flask\ctx.py", line 336, in match_request
    self.url_adapter.match(return_rule=True)
  File "C:\ProgramData\Anaconda3\envs\BI-dashboard\lib\site-packages\werkzeug\routing.py", line 1581, in match
    raise NotFound()
werkzeug.exceptions.NotFound: 404 Not Found: The requested URL was not found on the server.  If you entered the URL manually please check your spelling and try again.
2018-10-29 11:52:03,296 - da-service - WARNING - 访问了未知路径: [error: 404 Not Found: The requested URL was not found on the server.  If you entered the URL manually please check your spelling and try again.]
Traceback (most recent call last):
  File "C:\ProgramData\Anaconda3\envs\BI-dashboard\lib\site-packages\flask\app.py", line 1813, in full_dispatch_request
    rv = self.dispatch_request()
  File "C:\ProgramData\Anaconda3\envs\BI-dashboard\lib\site-packages\flask\app.py", line 1791, in dispatch_request
    self.raise_routing_exception(req)
  File "C:\ProgramData\Anaconda3\envs\BI-dashboard\lib\site-packages\flask\app.py", line 1774, in raise_routing_exception
    raise request.routing_exception
  File "C:\ProgramData\Anaconda3\envs\BI-dashboard\lib\site-packages\flask\ctx.py", line 336, in match_request
    self.url_adapter.match(return_rule=True)
  File "C:\ProgramData\Anaconda3\envs\BI-dashboard\lib\site-packages\werkzeug\routing.py", line 1581, in match
    raise NotFound()
werkzeug.exceptions.NotFound: 404 Not Found: The requested URL was not found on the server.  If you entered the URL manually please check your spelling and try again.
2018-10-29 11:52:03,513 - da-service - WARNING - 访问了未知路径: [error: 404 Not Found: The requested URL was not found on the server.  If you entered the URL manually please check your spelling and try again.]
Traceback (most recent call last):
  File "C:\ProgramData\Anaconda3\envs\BI-dashboard\lib\site-packages\flask\app.py", line 1813, in full_dispatch_request
    rv = self.dispatch_request()
  File "C:\ProgramData\Anaconda3\envs\BI-dashboard\lib\site-packages\flask\app.py", line 1791, in dispatch_request
    self.raise_routing_exception(req)
  File "C:\ProgramData\Anaconda3\envs\BI-dashboard\lib\site-packages\flask\app.py", line 1774, in raise_routing_exception
    raise request.routing_exception
  File "C:\ProgramData\Anaconda3\envs\BI-dashboard\lib\site-packages\flask\ctx.py", line 336, in match_request
    self.url_adapter.match(return_rule=True)
  File "C:\ProgramData\Anaconda3\envs\BI-dashboard\lib\site-packages\werkzeug\routing.py", line 1581, in match
    raise NotFound()
werkzeug.exceptions.NotFound: 404 Not Found: The requested URL was not found on the server.  If you entered the URL manually please check your spelling and try again.
2018-10-29 11:52:05,532 - da-service - WARNING - 访问了未知路径: [error: 404 Not Found: The requested URL was not found on the server.  If you entered the URL manually please check your spelling and try again.]
Traceback (most recent call last):
  File "C:\ProgramData\Anaconda3\envs\BI-dashboard\lib\site-packages\flask\app.py", line 1813, in full_dispatch_request
    rv = self.dispatch_request()
  File "C:\ProgramData\Anaconda3\envs\BI-dashboard\lib\site-packages\flask\app.py", line 1791, in dispatch_request
    self.raise_routing_exception(req)
  File "C:\ProgramData\Anaconda3\envs\BI-dashboard\lib\site-packages\flask\app.py", line 1774, in raise_routing_exception
    raise request.routing_exception
  File "C:\ProgramData\Anaconda3\envs\BI-dashboard\lib\site-packages\flask\ctx.py", line 336, in match_request
    self.url_adapter.match(return_rule=True)
  File "C:\ProgramData\Anaconda3\envs\BI-dashboard\lib\site-packages\werkzeug\routing.py", line 1581, in match
    raise NotFound()
werkzeug.exceptions.NotFound: 404 Not Found: The requested URL was not found on the server.  If you entered the URL manually please check your spelling and try again.
2018-10-29 11:52:05,545 - da-service - WARNING - 访问了未知路径: [error: 404 Not Found: The requested URL was not found on the server.  If you entered the URL manually please check your spelling and try again.]
Traceback (most recent call last):
  File "C:\ProgramData\Anaconda3\envs\BI-dashboard\lib\site-packages\flask\app.py", line 1813, in full_dispatch_request
    rv = self.dispatch_request()
  File "C:\ProgramData\Anaconda3\envs\BI-dashboard\lib\site-packages\flask\app.py", line 1791, in dispatch_request
    self.raise_routing_exception(req)
  File "C:\ProgramData\Anaconda3\envs\BI-dashboard\lib\site-packages\flask\app.py", line 1774, in raise_routing_exception
    raise request.routing_exception
  File "C:\ProgramData\Anaconda3\envs\BI-dashboard\lib\site-packages\flask\ctx.py", line 336, in match_request
    self.url_adapter.match(return_rule=True)
  File "C:\ProgramData\Anaconda3\envs\BI-dashboard\lib\site-packages\werkzeug\routing.py", line 1581, in match
    raise NotFound()
werkzeug.exceptions.NotFound: 404 Not Found: The requested URL was not found on the server.  If you entered the URL manually please check your spelling and try again.
2018-10-29 11:52:05,996 - da-service - WARNING - 访问了未知路径: [error: 404 Not Found: The requested URL was not found on the server.  If you entered the URL manually please check your spelling and try again.]
Traceback (most recent call last):
  File "C:\ProgramData\Anaconda3\envs\BI-dashboard\lib\site-packages\flask\app.py", line 1813, in full_dispatch_request
    rv = self.dispatch_request()
  File "C:\ProgramData\Anaconda3\envs\BI-dashboard\lib\site-packages\flask\app.py", line 1791, in dispatch_request
    self.raise_routing_exception(req)
  File "C:\ProgramData\Anaconda3\envs\BI-dashboard\lib\site-packages\flask\app.py", line 1774, in raise_routing_exception
    raise request.routing_exception
  File "C:\ProgramData\Anaconda3\envs\BI-dashboard\lib\site-packages\flask\ctx.py", line 336, in match_request
    self.url_adapter.match(return_rule=True)
  File "C:\ProgramData\Anaconda3\envs\BI-dashboard\lib\site-packages\werkzeug\routing.py", line 1581, in match
    raise NotFound()
werkzeug.exceptions.NotFound: 404 Not Found: The requested URL was not found on the server.  If you entered the URL manually please check your spelling and try again.
2018-10-29 11:52:26,671 - da-service - WARNING - 访问了未知路径: [error: 404 Not Found: The requested URL was not found on the server.  If you entered the URL manually please check your spelling and try again.]
Traceback (most recent call last):
  File "C:\ProgramData\Anaconda3\envs\BI-dashboard\lib\site-packages\flask\app.py", line 1813, in full_dispatch_request
    rv = self.dispatch_request()
  File "C:\ProgramData\Anaconda3\envs\BI-dashboard\lib\site-packages\flask\app.py", line 1799, in dispatch_request
    return self.view_functions[rule.endpoint](**req.view_args)
  File "C:\ProgramData\Anaconda3\envs\BI-dashboard\lib\site-packages\flask\helpers.py", line 976, in send_static_file
    cache_timeout=cache_timeout)
  File "C:\ProgramData\Anaconda3\envs\BI-dashboard\lib\site-packages\flask\helpers.py", line 709, in send_from_directory
    raise NotFound()
werkzeug.exceptions.NotFound: 404 Not Found: The requested URL was not found on the server.  If you entered the URL manually please check your spelling and try again.
2018-10-29 13:54:12,985 - da-service - WARNING - 访问了未知路径: [error: 404 Not Found: The requested URL was not found on the server.  If you entered the URL manually please check your spelling and try again.]
Traceback (most recent call last):
  File "C:\ProgramData\Anaconda3\envs\BI-dashboard\lib\site-packages\flask\app.py", line 1813, in full_dispatch_request
    rv = self.dispatch_request()
  File "C:\ProgramData\Anaconda3\envs\BI-dashboard\lib\site-packages\flask\app.py", line 1791, in dispatch_request
    self.raise_routing_exception(req)
  File "C:\ProgramData\Anaconda3\envs\BI-dashboard\lib\site-packages\flask\app.py", line 1774, in raise_routing_exception
    raise request.routing_exception
  File "C:\ProgramData\Anaconda3\envs\BI-dashboard\lib\site-packages\flask\ctx.py", line 336, in match_request
    self.url_adapter.match(return_rule=True)
  File "C:\ProgramData\Anaconda3\envs\BI-dashboard\lib\site-packages\werkzeug\routing.py", line 1581, in match
    raise NotFound()
werkzeug.exceptions.NotFound: 404 Not Found: The requested URL was not found on the server.  If you entered the URL manually please check your spelling and try again.
2018-10-29 13:54:13,008 - da-service - WARNING - 访问了未知路径: [error: 404 Not Found: The requested URL was not found on the server.  If you entered the URL manually please check your spelling and try again.]
Traceback (most recent call last):
  File "C:\ProgramData\Anaconda3\envs\BI-dashboard\lib\site-packages\flask\app.py", line 1813, in full_dispatch_request
    rv = self.dispatch_request()
  File "C:\ProgramData\Anaconda3\envs\BI-dashboard\lib\site-packages\flask\app.py", line 1791, in dispatch_request
    self.raise_routing_exception(req)
  File "C:\ProgramData\Anaconda3\envs\BI-dashboard\lib\site-packages\flask\app.py", line 1774, in raise_routing_exception
    raise request.routing_exception
  File "C:\ProgramData\Anaconda3\envs\BI-dashboard\lib\site-packages\flask\ctx.py", line 336, in match_request
    self.url_adapter.match(return_rule=True)
  File "C:\ProgramData\Anaconda3\envs\BI-dashboard\lib\site-packages\werkzeug\routing.py", line 1581, in match
    raise NotFound()
werkzeug.exceptions.NotFound: 404 Not Found: The requested URL was not found on the server.  If you entered the URL manually please check your spelling and try again.
2018-10-29 13:54:13,587 - da-service - WARNING - 访问了未知路径: [error: 404 Not Found: The requested URL was not found on the server.  If you entered the URL manually please check your spelling and try again.]
Traceback (most recent call last):
  File "C:\ProgramData\Anaconda3\envs\BI-dashboard\lib\site-packages\flask\app.py", line 1813, in full_dispatch_request
    rv = self.dispatch_request()
  File "C:\ProgramData\Anaconda3\envs\BI-dashboard\lib\site-packages\flask\app.py", line 1791, in dispatch_request
    self.raise_routing_exception(req)
  File "C:\ProgramData\Anaconda3\envs\BI-dashboard\lib\site-packages\flask\app.py", line 1774, in raise_routing_exception
    raise request.routing_exception
  File "C:\ProgramData\Anaconda3\envs\BI-dashboard\lib\site-packages\flask\ctx.py", line 336, in match_request
    self.url_adapter.match(return_rule=True)
  File "C:\ProgramData\Anaconda3\envs\BI-dashboard\lib\site-packages\werkzeug\routing.py", line 1581, in match
    raise NotFound()
werkzeug.exceptions.NotFound: 404 Not Found: The requested URL was not found on the server.  If you entered the URL manually please check your spelling and try again.
2018-10-29 15:31:37,542 - da-service - WARNING - 访问了未知路径: [error: 404 Not Found: The requested URL was not found on the server.  If you entered the URL manually please check your spelling and try again.]
Traceback (most recent call last):
  File "C:\ProgramData\Anaconda3\envs\BI-dashboard\lib\site-packages\flask\app.py", line 1813, in full_dispatch_request
    rv = self.dispatch_request()
  File "C:\ProgramData\Anaconda3\envs\BI-dashboard\lib\site-packages\flask\app.py", line 1791, in dispatch_request
    self.raise_routing_exception(req)
  File "C:\ProgramData\Anaconda3\envs\BI-dashboard\lib\site-packages\flask\app.py", line 1774, in raise_routing_exception
    raise request.routing_exception
  File "C:\ProgramData\Anaconda3\envs\BI-dashboard\lib\site-packages\flask\ctx.py", line 336, in match_request
    self.url_adapter.match(return_rule=True)
  File "C:\ProgramData\Anaconda3\envs\BI-dashboard\lib\site-packages\werkzeug\routing.py", line 1581, in match
    raise NotFound()
werkzeug.exceptions.NotFound: 404 Not Found: The requested URL was not found on the server.  If you entered the URL manually please check your spelling and try again.
2018-10-29 15:31:37,585 - da-service - WARNING - 访问了未知路径: [error: 404 Not Found: The requested URL was not found on the server.  If you entered the URL manually please check your spelling and try again.]
Traceback (most recent call last):
  File "C:\ProgramData\Anaconda3\envs\BI-dashboard\lib\site-packages\flask\app.py", line 1813, in full_dispatch_request
    rv = self.dispatch_request()
  File "C:\ProgramData\Anaconda3\envs\BI-dashboard\lib\site-packages\flask\app.py", line 1791, in dispatch_request
    self.raise_routing_exception(req)
  File "C:\ProgramData\Anaconda3\envs\BI-dashboard\lib\site-packages\flask\app.py", line 1774, in raise_routing_exception
    raise request.routing_exception
  File "C:\ProgramData\Anaconda3\envs\BI-dashboard\lib\site-packages\flask\ctx.py", line 336, in match_request
    self.url_adapter.match(return_rule=True)
  File "C:\ProgramData\Anaconda3\envs\BI-dashboard\lib\site-packages\werkzeug\routing.py", line 1581, in match
    raise NotFound()
werkzeug.exceptions.NotFound: 404 Not Found: The requested URL was not found on the server.  If you entered the URL manually please check your spelling and try again.
2018-10-29 15:31:38,123 - da-service - WARNING - 访问了未知路径: [error: 404 Not Found: The requested URL was not found on the server.  If you entered the URL manually please check your spelling and try again.]
Traceback (most recent call last):
  File "C:\ProgramData\Anaconda3\envs\BI-dashboard\lib\site-packages\flask\app.py", line 1813, in full_dispatch_request
    rv = self.dispatch_request()
  File "C:\ProgramData\Anaconda3\envs\BI-dashboard\lib\site-packages\flask\app.py", line 1791, in dispatch_request
    self.raise_routing_exception(req)
  File "C:\ProgramData\Anaconda3\envs\BI-dashboard\lib\site-packages\flask\app.py", line 1774, in raise_routing_exception
    raise request.routing_exception
  File "C:\ProgramData\Anaconda3\envs\BI-dashboard\lib\site-packages\flask\ctx.py", line 336, in match_request
    self.url_adapter.match(return_rule=True)
  File "C:\ProgramData\Anaconda3\envs\BI-dashboard\lib\site-packages\werkzeug\routing.py", line 1581, in match
    raise NotFound()
werkzeug.exceptions.NotFound: 404 Not Found: The requested URL was not found on the server.  If you entered the URL manually please check your spelling and try again.
2018-10-29 15:33:14,054 - da-service - WARNING - 访问了未知路径: [error: 404 Not Found: The requested URL was not found on the server.  If you entered the URL manually please check your spelling and try again.]
Traceback (most recent call last):
  File "C:\ProgramData\Anaconda3\envs\BI-dashboard\lib\site-packages\flask\app.py", line 1813, in full_dispatch_request
    rv = self.dispatch_request()
  File "C:\ProgramData\Anaconda3\envs\BI-dashboard\lib\site-packages\flask\app.py", line 1791, in dispatch_request
    self.raise_routing_exception(req)
  File "C:\ProgramData\Anaconda3\envs\BI-dashboard\lib\site-packages\flask\app.py", line 1774, in raise_routing_exception
    raise request.routing_exception
  File "C:\ProgramData\Anaconda3\envs\BI-dashboard\lib\site-packages\flask\ctx.py", line 336, in match_request
    self.url_adapter.match(return_rule=True)
  File "C:\ProgramData\Anaconda3\envs\BI-dashboard\lib\site-packages\werkzeug\routing.py", line 1581, in match
    raise NotFound()
werkzeug.exceptions.NotFound: 404 Not Found: The requested URL was not found on the server.  If you entered the URL manually please check your spelling and try again.
2018-10-29 15:33:14,088 - da-service - WARNING - 访问了未知路径: [error: 404 Not Found: The requested URL was not found on the server.  If you entered the URL manually please check your spelling and try again.]
Traceback (most recent call last):
  File "C:\ProgramData\Anaconda3\envs\BI-dashboard\lib\site-packages\flask\app.py", line 1813, in full_dispatch_request
    rv = self.dispatch_request()
  File "C:\ProgramData\Anaconda3\envs\BI-dashboard\lib\site-packages\flask\app.py", line 1791, in dispatch_request
    self.raise_routing_exception(req)
  File "C:\ProgramData\Anaconda3\envs\BI-dashboard\lib\site-packages\flask\app.py", line 1774, in raise_routing_exception
    raise request.routing_exception
  File "C:\ProgramData\Anaconda3\envs\BI-dashboard\lib\site-packages\flask\ctx.py", line 336, in match_request
    self.url_adapter.match(return_rule=True)
  File "C:\ProgramData\Anaconda3\envs\BI-dashboard\lib\site-packages\werkzeug\routing.py", line 1581, in match
    raise NotFound()
werkzeug.exceptions.NotFound: 404 Not Found: The requested URL was not found on the server.  If you entered the URL manually please check your spelling and try again.
2018-10-29 15:33:14,907 - da-service - WARNING - 访问了未知路径: [error: 404 Not Found: The requested URL was not found on the server.  If you entered the URL manually please check your spelling and try again.]
Traceback (most recent call last):
  File "C:\ProgramData\Anaconda3\envs\BI-dashboard\lib\site-packages\flask\app.py", line 1813, in full_dispatch_request
    rv = self.dispatch_request()
  File "C:\ProgramData\Anaconda3\envs\BI-dashboard\lib\site-packages\flask\app.py", line 1791, in dispatch_request
    self.raise_routing_exception(req)
  File "C:\ProgramData\Anaconda3\envs\BI-dashboard\lib\site-packages\flask\app.py", line 1774, in raise_routing_exception
    raise request.routing_exception
  File "C:\ProgramData\Anaconda3\envs\BI-dashboard\lib\site-packages\flask\ctx.py", line 336, in match_request
    self.url_adapter.match(return_rule=True)
  File "C:\ProgramData\Anaconda3\envs\BI-dashboard\lib\site-packages\werkzeug\routing.py", line 1581, in match
    raise NotFound()
werkzeug.exceptions.NotFound: 404 Not Found: The requested URL was not found on the server.  If you entered the URL manually please check your spelling and try again.
2018-10-29 15:33:54,996 - da-service - WARNING - 访问了未知路径: [error: 404 Not Found: The requested URL was not found on the server.  If you entered the URL manually please check your spelling and try again.]
Traceback (most recent call last):
  File "C:\ProgramData\Anaconda3\envs\BI-dashboard\lib\site-packages\flask\app.py", line 1813, in full_dispatch_request
    rv = self.dispatch_request()
  File "C:\ProgramData\Anaconda3\envs\BI-dashboard\lib\site-packages\flask\app.py", line 1791, in dispatch_request
    self.raise_routing_exception(req)
  File "C:\ProgramData\Anaconda3\envs\BI-dashboard\lib\site-packages\flask\app.py", line 1774, in raise_routing_exception
    raise request.routing_exception
  File "C:\ProgramData\Anaconda3\envs\BI-dashboard\lib\site-packages\flask\ctx.py", line 336, in match_request
    self.url_adapter.match(return_rule=True)
  File "C:\ProgramData\Anaconda3\envs\BI-dashboard\lib\site-packages\werkzeug\routing.py", line 1581, in match
    raise NotFound()
werkzeug.exceptions.NotFound: 404 Not Found: The requested URL was not found on the server.  If you entered the URL manually please check your spelling and try again.
2018-10-29 15:33:55,025 - da-service - WARNING - 访问了未知路径: [error: 404 Not Found: The requested URL was not found on the server.  If you entered the URL manually please check your spelling and try again.]
Traceback (most recent call last):
  File "C:\ProgramData\Anaconda3\envs\BI-dashboard\lib\site-packages\flask\app.py", line 1813, in full_dispatch_request
    rv = self.dispatch_request()
  File "C:\ProgramData\Anaconda3\envs\BI-dashboard\lib\site-packages\flask\app.py", line 1791, in dispatch_request
    self.raise_routing_exception(req)
  File "C:\ProgramData\Anaconda3\envs\BI-dashboard\lib\site-packages\flask\app.py", line 1774, in raise_routing_exception
    raise request.routing_exception
  File "C:\ProgramData\Anaconda3\envs\BI-dashboard\lib\site-packages\flask\ctx.py", line 336, in match_request
    self.url_adapter.match(return_rule=True)
  File "C:\ProgramData\Anaconda3\envs\BI-dashboard\lib\site-packages\werkzeug\routing.py", line 1581, in match
    raise NotFound()
werkzeug.exceptions.NotFound: 404 Not Found: The requested URL was not found on the server.  If you entered the URL manually please check your spelling and try again.
2018-10-29 15:33:56,190 - da-service - WARNING - 访问了未知路径: [error: 404 Not Found: The requested URL was not found on the server.  If you entered the URL manually please check your spelling and try again.]
Traceback (most recent call last):
  File "C:\ProgramData\Anaconda3\envs\BI-dashboard\lib\site-packages\flask\app.py", line 1813, in full_dispatch_request
    rv = self.dispatch_request()
  File "C:\ProgramData\Anaconda3\envs\BI-dashboard\lib\site-packages\flask\app.py", line 1791, in dispatch_request
    self.raise_routing_exception(req)
  File "C:\ProgramData\Anaconda3\envs\BI-dashboard\lib\site-packages\flask\app.py", line 1774, in raise_routing_exception
    raise request.routing_exception
  File "C:\ProgramData\Anaconda3\envs\BI-dashboard\lib\site-packages\flask\ctx.py", line 336, in match_request
    self.url_adapter.match(return_rule=True)
  File "C:\ProgramData\Anaconda3\envs\BI-dashboard\lib\site-packages\werkzeug\routing.py", line 1581, in match
    raise NotFound()
werkzeug.exceptions.NotFound: 404 Not Found: The requested URL was not found on the server.  If you entered the URL manually please check your spelling and try again.
2018-10-29 15:34:07,763 - da-service - WARNING - 访问了未知路径: [error: 404 Not Found: The requested URL was not found on the server.  If you entered the URL manually please check your spelling and try again.]
Traceback (most recent call last):
  File "C:\ProgramData\Anaconda3\envs\BI-dashboard\lib\site-packages\flask\app.py", line 1813, in full_dispatch_request
    rv = self.dispatch_request()
  File "C:\ProgramData\Anaconda3\envs\BI-dashboard\lib\site-packages\flask\app.py", line 1791, in dispatch_request
    self.raise_routing_exception(req)
  File "C:\ProgramData\Anaconda3\envs\BI-dashboard\lib\site-packages\flask\app.py", line 1774, in raise_routing_exception
    raise request.routing_exception
  File "C:\ProgramData\Anaconda3\envs\BI-dashboard\lib\site-packages\flask\ctx.py", line 336, in match_request
    self.url_adapter.match(return_rule=True)
  File "C:\ProgramData\Anaconda3\envs\BI-dashboard\lib\site-packages\werkzeug\routing.py", line 1581, in match
    raise NotFound()
werkzeug.exceptions.NotFound: 404 Not Found: The requested URL was not found on the server.  If you entered the URL manually please check your spelling and try again.
2018-10-29 15:35:05,465 - da-service - WARNING - 访问了未知路径: [error: 404 Not Found: The requested URL was not found on the server.  If you entered the URL manually please check your spelling and try again.]
Traceback (most recent call last):
  File "C:\ProgramData\Anaconda3\envs\BI-dashboard\lib\site-packages\flask\app.py", line 1813, in full_dispatch_request
    rv = self.dispatch_request()
  File "C:\ProgramData\Anaconda3\envs\BI-dashboard\lib\site-packages\flask\app.py", line 1791, in dispatch_request
    self.raise_routing_exception(req)
  File "C:\ProgramData\Anaconda3\envs\BI-dashboard\lib\site-packages\flask\app.py", line 1774, in raise_routing_exception
    raise request.routing_exception
  File "C:\ProgramData\Anaconda3\envs\BI-dashboard\lib\site-packages\flask\ctx.py", line 336, in match_request
    self.url_adapter.match(return_rule=True)
  File "C:\ProgramData\Anaconda3\envs\BI-dashboard\lib\site-packages\werkzeug\routing.py", line 1581, in match
    raise NotFound()
werkzeug.exceptions.NotFound: 404 Not Found: The requested URL was not found on the server.  If you entered the URL manually please check your spelling and try again.
2018-10-29 15:35:05,495 - da-service - WARNING - 访问了未知路径: [error: 404 Not Found: The requested URL was not found on the server.  If you entered the URL manually please check your spelling and try again.]
Traceback (most recent call last):
  File "C:\ProgramData\Anaconda3\envs\BI-dashboard\lib\site-packages\flask\app.py", line 1813, in full_dispatch_request
    rv = self.dispatch_request()
  File "C:\ProgramData\Anaconda3\envs\BI-dashboard\lib\site-packages\flask\app.py", line 1791, in dispatch_request
    self.raise_routing_exception(req)
  File "C:\ProgramData\Anaconda3\envs\BI-dashboard\lib\site-packages\flask\app.py", line 1774, in raise_routing_exception
    raise request.routing_exception
  File "C:\ProgramData\Anaconda3\envs\BI-dashboard\lib\site-packages\flask\ctx.py", line 336, in match_request
    self.url_adapter.match(return_rule=True)
  File "C:\ProgramData\Anaconda3\envs\BI-dashboard\lib\site-packages\werkzeug\routing.py", line 1581, in match
    raise NotFound()
werkzeug.exceptions.NotFound: 404 Not Found: The requested URL was not found on the server.  If you entered the URL manually please check your spelling and try again.
2018-10-29 15:35:06,993 - da-service - WARNING - 访问了未知路径: [error: 404 Not Found: The requested URL was not found on the server.  If you entered the URL manually please check your spelling and try again.]
Traceback (most recent call last):
  File "C:\ProgramData\Anaconda3\envs\BI-dashboard\lib\site-packages\flask\app.py", line 1813, in full_dispatch_request
    rv = self.dispatch_request()
  File "C:\ProgramData\Anaconda3\envs\BI-dashboard\lib\site-packages\flask\app.py", line 1791, in dispatch_request
    self.raise_routing_exception(req)
  File "C:\ProgramData\Anaconda3\envs\BI-dashboard\lib\site-packages\flask\app.py", line 1774, in raise_routing_exception
    raise request.routing_exception
  File "C:\ProgramData\Anaconda3\envs\BI-dashboard\lib\site-packages\flask\ctx.py", line 336, in match_request
    self.url_adapter.match(return_rule=True)
  File "C:\ProgramData\Anaconda3\envs\BI-dashboard\lib\site-packages\werkzeug\routing.py", line 1581, in match
    raise NotFound()
werkzeug.exceptions.NotFound: 404 Not Found: The requested URL was not found on the server.  If you entered the URL manually please check your spelling and try again.
2018-10-29 15:57:50,812 - da-service - WARNING - 访问了未知路径: [error: 404 Not Found: The requested URL was not found on the server.  If you entered the URL manually please check your spelling and try again.]
Traceback (most recent call last):
  File "C:\ProgramData\Anaconda3\envs\BI-dashboard\lib\site-packages\flask\app.py", line 1813, in full_dispatch_request
    rv = self.dispatch_request()
  File "C:\ProgramData\Anaconda3\envs\BI-dashboard\lib\site-packages\flask\app.py", line 1791, in dispatch_request
    self.raise_routing_exception(req)
  File "C:\ProgramData\Anaconda3\envs\BI-dashboard\lib\site-packages\flask\app.py", line 1774, in raise_routing_exception
    raise request.routing_exception
  File "C:\ProgramData\Anaconda3\envs\BI-dashboard\lib\site-packages\flask\ctx.py", line 336, in match_request
    self.url_adapter.match(return_rule=True)
  File "C:\ProgramData\Anaconda3\envs\BI-dashboard\lib\site-packages\werkzeug\routing.py", line 1581, in match
    raise NotFound()
werkzeug.exceptions.NotFound: 404 Not Found: The requested URL was not found on the server.  If you entered the URL manually please check your spelling and try again.
2018-10-29 15:57:50,849 - da-service - WARNING - 访问了未知路径: [error: 404 Not Found: The requested URL was not found on the server.  If you entered the URL manually please check your spelling and try again.]
Traceback (most recent call last):
  File "C:\ProgramData\Anaconda3\envs\BI-dashboard\lib\site-packages\flask\app.py", line 1813, in full_dispatch_request
    rv = self.dispatch_request()
  File "C:\ProgramData\Anaconda3\envs\BI-dashboard\lib\site-packages\flask\app.py", line 1791, in dispatch_request
    self.raise_routing_exception(req)
  File "C:\ProgramData\Anaconda3\envs\BI-dashboard\lib\site-packages\flask\app.py", line 1774, in raise_routing_exception
    raise request.routing_exception
  File "C:\ProgramData\Anaconda3\envs\BI-dashboard\lib\site-packages\flask\ctx.py", line 336, in match_request
    self.url_adapter.match(return_rule=True)
  File "C:\ProgramData\Anaconda3\envs\BI-dashboard\lib\site-packages\werkzeug\routing.py", line 1581, in match
    raise NotFound()
werkzeug.exceptions.NotFound: 404 Not Found: The requested URL was not found on the server.  If you entered the URL manually please check your spelling and try again.
2018-10-29 15:57:51,773 - da-service - WARNING - 访问了未知路径: [error: 404 Not Found: The requested URL was not found on the server.  If you entered the URL manually please check your spelling and try again.]
Traceback (most recent call last):
  File "C:\ProgramData\Anaconda3\envs\BI-dashboard\lib\site-packages\flask\app.py", line 1813, in full_dispatch_request
    rv = self.dispatch_request()
  File "C:\ProgramData\Anaconda3\envs\BI-dashboard\lib\site-packages\flask\app.py", line 1791, in dispatch_request
    self.raise_routing_exception(req)
  File "C:\ProgramData\Anaconda3\envs\BI-dashboard\lib\site-packages\flask\app.py", line 1774, in raise_routing_exception
    raise request.routing_exception
  File "C:\ProgramData\Anaconda3\envs\BI-dashboard\lib\site-packages\flask\ctx.py", line 336, in match_request
    self.url_adapter.match(return_rule=True)
  File "C:\ProgramData\Anaconda3\envs\BI-dashboard\lib\site-packages\werkzeug\routing.py", line 1581, in match
    raise NotFound()
werkzeug.exceptions.NotFound: 404 Not Found: The requested URL was not found on the server.  If you entered the URL manually please check your spelling and try again.
2018-10-29 16:42:44,071 - da-service - WARNING - 访问了未知路径: [error: 404 Not Found: The requested URL was not found on the server.  If you entered the URL manually please check your spelling and try again.]
Traceback (most recent call last):
  File "C:\ProgramData\Anaconda3\envs\BI-dashboard\lib\site-packages\flask\app.py", line 1813, in full_dispatch_request
    rv = self.dispatch_request()
  File "C:\ProgramData\Anaconda3\envs\BI-dashboard\lib\site-packages\flask\app.py", line 1791, in dispatch_request
    self.raise_routing_exception(req)
  File "C:\ProgramData\Anaconda3\envs\BI-dashboard\lib\site-packages\flask\app.py", line 1774, in raise_routing_exception
    raise request.routing_exception
  File "C:\ProgramData\Anaconda3\envs\BI-dashboard\lib\site-packages\flask\ctx.py", line 336, in match_request
    self.url_adapter.match(return_rule=True)
  File "C:\ProgramData\Anaconda3\envs\BI-dashboard\lib\site-packages\werkzeug\routing.py", line 1581, in match
    raise NotFound()
werkzeug.exceptions.NotFound: 404 Not Found: The requested URL was not found on the server.  If you entered the URL manually please check your spelling and try again.
2018-10-29 16:42:44,092 - da-service - WARNING - 访问了未知路径: [error: 404 Not Found: The requested URL was not found on the server.  If you entered the URL manually please check your spelling and try again.]
Traceback (most recent call last):
  File "C:\ProgramData\Anaconda3\envs\BI-dashboard\lib\site-packages\flask\app.py", line 1813, in full_dispatch_request
    rv = self.dispatch_request()
  File "C:\ProgramData\Anaconda3\envs\BI-dashboard\lib\site-packages\flask\app.py", line 1791, in dispatch_request
    self.raise_routing_exception(req)
  File "C:\ProgramData\Anaconda3\envs\BI-dashboard\lib\site-packages\flask\app.py", line 1774, in raise_routing_exception
    raise request.routing_exception
  File "C:\ProgramData\Anaconda3\envs\BI-dashboard\lib\site-packages\flask\ctx.py", line 336, in match_request
    self.url_adapter.match(return_rule=True)
  File "C:\ProgramData\Anaconda3\envs\BI-dashboard\lib\site-packages\werkzeug\routing.py", line 1581, in match
    raise NotFound()
werkzeug.exceptions.NotFound: 404 Not Found: The requested URL was not found on the server.  If you entered the URL manually please check your spelling and try again.
2018-10-29 16:42:44,884 - da-service - WARNING - 访问了未知路径: [error: 404 Not Found: The requested URL was not found on the server.  If you entered the URL manually please check your spelling and try again.]
Traceback (most recent call last):
  File "C:\ProgramData\Anaconda3\envs\BI-dashboard\lib\site-packages\flask\app.py", line 1813, in full_dispatch_request
    rv = self.dispatch_request()
  File "C:\ProgramData\Anaconda3\envs\BI-dashboard\lib\site-packages\flask\app.py", line 1791, in dispatch_request
    self.raise_routing_exception(req)
  File "C:\ProgramData\Anaconda3\envs\BI-dashboard\lib\site-packages\flask\app.py", line 1774, in raise_routing_exception
    raise request.routing_exception
  File "C:\ProgramData\Anaconda3\envs\BI-dashboard\lib\site-packages\flask\ctx.py", line 336, in match_request
    self.url_adapter.match(return_rule=True)
  File "C:\ProgramData\Anaconda3\envs\BI-dashboard\lib\site-packages\werkzeug\routing.py", line 1581, in match
    raise NotFound()
werkzeug.exceptions.NotFound: 404 Not Found: The requested URL was not found on the server.  If you entered the URL manually please check your spelling and try again.
2018-10-29 16:43:51,753 - da-service - WARNING - 访问了未知路径: [error: 404 Not Found: The requested URL was not found on the server.  If you entered the URL manually please check your spelling and try again.]
Traceback (most recent call last):
  File "C:\ProgramData\Anaconda3\envs\BI-dashboard\lib\site-packages\flask\app.py", line 1813, in full_dispatch_request
    rv = self.dispatch_request()
  File "C:\ProgramData\Anaconda3\envs\BI-dashboard\lib\site-packages\flask\app.py", line 1791, in dispatch_request
    self.raise_routing_exception(req)
  File "C:\ProgramData\Anaconda3\envs\BI-dashboard\lib\site-packages\flask\app.py", line 1774, in raise_routing_exception
    raise request.routing_exception
  File "C:\ProgramData\Anaconda3\envs\BI-dashboard\lib\site-packages\flask\ctx.py", line 336, in match_request
    self.url_adapter.match(return_rule=True)
  File "C:\ProgramData\Anaconda3\envs\BI-dashboard\lib\site-packages\werkzeug\routing.py", line 1581, in match
    raise NotFound()
werkzeug.exceptions.NotFound: 404 Not Found: The requested URL was not found on the server.  If you entered the URL manually please check your spelling and try again.
2018-10-29 16:43:51,779 - da-service - WARNING - 访问了未知路径: [error: 404 Not Found: The requested URL was not found on the server.  If you entered the URL manually please check your spelling and try again.]
Traceback (most recent call last):
  File "C:\ProgramData\Anaconda3\envs\BI-dashboard\lib\site-packages\flask\app.py", line 1813, in full_dispatch_request
    rv = self.dispatch_request()
  File "C:\ProgramData\Anaconda3\envs\BI-dashboard\lib\site-packages\flask\app.py", line 1791, in dispatch_request
    self.raise_routing_exception(req)
  File "C:\ProgramData\Anaconda3\envs\BI-dashboard\lib\site-packages\flask\app.py", line 1774, in raise_routing_exception
    raise request.routing_exception
  File "C:\ProgramData\Anaconda3\envs\BI-dashboard\lib\site-packages\flask\ctx.py", line 336, in match_request
    self.url_adapter.match(return_rule=True)
  File "C:\ProgramData\Anaconda3\envs\BI-dashboard\lib\site-packages\werkzeug\routing.py", line 1581, in match
    raise NotFound()
werkzeug.exceptions.NotFound: 404 Not Found: The requested URL was not found on the server.  If you entered the URL manually please check your spelling and try again.
2018-10-29 16:43:53,246 - da-service - WARNING - 访问了未知路径: [error: 404 Not Found: The requested URL was not found on the server.  If you entered the URL manually please check your spelling and try again.]
Traceback (most recent call last):
  File "C:\ProgramData\Anaconda3\envs\BI-dashboard\lib\site-packages\flask\app.py", line 1813, in full_dispatch_request
    rv = self.dispatch_request()
  File "C:\ProgramData\Anaconda3\envs\BI-dashboard\lib\site-packages\flask\app.py", line 1791, in dispatch_request
    self.raise_routing_exception(req)
  File "C:\ProgramData\Anaconda3\envs\BI-dashboard\lib\site-packages\flask\app.py", line 1774, in raise_routing_exception
    raise request.routing_exception
  File "C:\ProgramData\Anaconda3\envs\BI-dashboard\lib\site-packages\flask\ctx.py", line 336, in match_request
    self.url_adapter.match(return_rule=True)
  File "C:\ProgramData\Anaconda3\envs\BI-dashboard\lib\site-packages\werkzeug\routing.py", line 1581, in match
    raise NotFound()
werkzeug.exceptions.NotFound: 404 Not Found: The requested URL was not found on the server.  If you entered the URL manually please check your spelling and try again.
2018-10-29 16:43:56,576 - da-service - WARNING - 访问了未知路径: [error: 404 Not Found: The requested URL was not found on the server.  If you entered the URL manually please check your spelling and try again.]
Traceback (most recent call last):
  File "C:\ProgramData\Anaconda3\envs\BI-dashboard\lib\site-packages\flask\app.py", line 1813, in full_dispatch_request
    rv = self.dispatch_request()
  File "C:\ProgramData\Anaconda3\envs\BI-dashboard\lib\site-packages\flask\app.py", line 1791, in dispatch_request
    self.raise_routing_exception(req)
  File "C:\ProgramData\Anaconda3\envs\BI-dashboard\lib\site-packages\flask\app.py", line 1774, in raise_routing_exception
    raise request.routing_exception
  File "C:\ProgramData\Anaconda3\envs\BI-dashboard\lib\site-packages\flask\ctx.py", line 336, in match_request
    self.url_adapter.match(return_rule=True)
  File "C:\ProgramData\Anaconda3\envs\BI-dashboard\lib\site-packages\werkzeug\routing.py", line 1581, in match
    raise NotFound()
werkzeug.exceptions.NotFound: 404 Not Found: The requested URL was not found on the server.  If you entered the URL manually please check your spelling and try again.
2018-10-29 16:43:56,614 - da-service - WARNING - 访问了未知路径: [error: 404 Not Found: The requested URL was not found on the server.  If you entered the URL manually please check your spelling and try again.]
Traceback (most recent call last):
  File "C:\ProgramData\Anaconda3\envs\BI-dashboard\lib\site-packages\flask\app.py", line 1813, in full_dispatch_request
    rv = self.dispatch_request()
  File "C:\ProgramData\Anaconda3\envs\BI-dashboard\lib\site-packages\flask\app.py", line 1791, in dispatch_request
    self.raise_routing_exception(req)
  File "C:\ProgramData\Anaconda3\envs\BI-dashboard\lib\site-packages\flask\app.py", line 1774, in raise_routing_exception
    raise request.routing_exception
  File "C:\ProgramData\Anaconda3\envs\BI-dashboard\lib\site-packages\flask\ctx.py", line 336, in match_request
    self.url_adapter.match(return_rule=True)
  File "C:\ProgramData\Anaconda3\envs\BI-dashboard\lib\site-packages\werkzeug\routing.py", line 1581, in match
    raise NotFound()
werkzeug.exceptions.NotFound: 404 Not Found: The requested URL was not found on the server.  If you entered the URL manually please check your spelling and try again.
2018-10-29 16:43:57,259 - da-service - WARNING - 访问了未知路径: [error: 404 Not Found: The requested URL was not found on the server.  If you entered the URL manually please check your spelling and try again.]
Traceback (most recent call last):
  File "C:\ProgramData\Anaconda3\envs\BI-dashboard\lib\site-packages\flask\app.py", line 1813, in full_dispatch_request
    rv = self.dispatch_request()
  File "C:\ProgramData\Anaconda3\envs\BI-dashboard\lib\site-packages\flask\app.py", line 1791, in dispatch_request
    self.raise_routing_exception(req)
  File "C:\ProgramData\Anaconda3\envs\BI-dashboard\lib\site-packages\flask\app.py", line 1774, in raise_routing_exception
    raise request.routing_exception
  File "C:\ProgramData\Anaconda3\envs\BI-dashboard\lib\site-packages\flask\ctx.py", line 336, in match_request
    self.url_adapter.match(return_rule=True)
  File "C:\ProgramData\Anaconda3\envs\BI-dashboard\lib\site-packages\werkzeug\routing.py", line 1581, in match
    raise NotFound()
werkzeug.exceptions.NotFound: 404 Not Found: The requested URL was not found on the server.  If you entered the URL manually please check your spelling and try again.
2018-10-29 16:44:05,496 - da-service - WARNING - 访问了未知路径: [error: 404 Not Found: The requested URL was not found on the server.  If you entered the URL manually please check your spelling and try again.]
Traceback (most recent call last):
  File "C:\ProgramData\Anaconda3\envs\BI-dashboard\lib\site-packages\flask\app.py", line 1813, in full_dispatch_request
    rv = self.dispatch_request()
  File "C:\ProgramData\Anaconda3\envs\BI-dashboard\lib\site-packages\flask\app.py", line 1799, in dispatch_request
    return self.view_functions[rule.endpoint](**req.view_args)
  File "C:\ProgramData\Anaconda3\envs\BI-dashboard\lib\site-packages\flask\helpers.py", line 976, in send_static_file
    cache_timeout=cache_timeout)
  File "C:\ProgramData\Anaconda3\envs\BI-dashboard\lib\site-packages\flask\helpers.py", line 709, in send_from_directory
    raise NotFound()
werkzeug.exceptions.NotFound: 404 Not Found: The requested URL was not found on the server.  If you entered the URL manually please check your spelling and try again.
2018-10-29 16:44:07,868 - da-service - WARNING - 访问了未知路径: [error: 404 Not Found: The requested URL was not found on the server.  If you entered the URL manually please check your spelling and try again.]
Traceback (most recent call last):
  File "C:\ProgramData\Anaconda3\envs\BI-dashboard\lib\site-packages\flask\app.py", line 1813, in full_dispatch_request
    rv = self.dispatch_request()
  File "C:\ProgramData\Anaconda3\envs\BI-dashboard\lib\site-packages\flask\app.py", line 1791, in dispatch_request
    self.raise_routing_exception(req)
  File "C:\ProgramData\Anaconda3\envs\BI-dashboard\lib\site-packages\flask\app.py", line 1774, in raise_routing_exception
    raise request.routing_exception
  File "C:\ProgramData\Anaconda3\envs\BI-dashboard\lib\site-packages\flask\ctx.py", line 336, in match_request
    self.url_adapter.match(return_rule=True)
  File "C:\ProgramData\Anaconda3\envs\BI-dashboard\lib\site-packages\werkzeug\routing.py", line 1581, in match
    raise NotFound()
werkzeug.exceptions.NotFound: 404 Not Found: The requested URL was not found on the server.  If you entered the URL manually please check your spelling and try again.
2018-10-29 16:46:37,180 - da-service - WARNING - 访问了未知路径: [error: 404 Not Found: The requested URL was not found on the server.  If you entered the URL manually please check your spelling and try again.]
Traceback (most recent call last):
  File "C:\ProgramData\Anaconda3\envs\BI-dashboard\lib\site-packages\flask\app.py", line 1813, in full_dispatch_request
    rv = self.dispatch_request()
  File "C:\ProgramData\Anaconda3\envs\BI-dashboard\lib\site-packages\flask\app.py", line 1791, in dispatch_request
    self.raise_routing_exception(req)
  File "C:\ProgramData\Anaconda3\envs\BI-dashboard\lib\site-packages\flask\app.py", line 1774, in raise_routing_exception
    raise request.routing_exception
  File "C:\ProgramData\Anaconda3\envs\BI-dashboard\lib\site-packages\flask\ctx.py", line 336, in match_request
    self.url_adapter.match(return_rule=True)
  File "C:\ProgramData\Anaconda3\envs\BI-dashboard\lib\site-packages\werkzeug\routing.py", line 1581, in match
    raise NotFound()
werkzeug.exceptions.NotFound: 404 Not Found: The requested URL was not found on the server.  If you entered the URL manually please check your spelling and try again.
2018-10-29 16:46:37,193 - da-service - WARNING - 访问了未知路径: [error: 404 Not Found: The requested URL was not found on the server.  If you entered the URL manually please check your spelling and try again.]
Traceback (most recent call last):
  File "C:\ProgramData\Anaconda3\envs\BI-dashboard\lib\site-packages\flask\app.py", line 1813, in full_dispatch_request
    rv = self.dispatch_request()
  File "C:\ProgramData\Anaconda3\envs\BI-dashboard\lib\site-packages\flask\app.py", line 1791, in dispatch_request
    self.raise_routing_exception(req)
  File "C:\ProgramData\Anaconda3\envs\BI-dashboard\lib\site-packages\flask\app.py", line 1774, in raise_routing_exception
    raise request.routing_exception
  File "C:\ProgramData\Anaconda3\envs\BI-dashboard\lib\site-packages\flask\ctx.py", line 336, in match_request
    self.url_adapter.match(return_rule=True)
  File "C:\ProgramData\Anaconda3\envs\BI-dashboard\lib\site-packages\werkzeug\routing.py", line 1581, in match
    raise NotFound()
werkzeug.exceptions.NotFound: 404 Not Found: The requested URL was not found on the server.  If you entered the URL manually please check your spelling and try again.
2018-10-29 16:46:38,023 - da-service - WARNING - 访问了未知路径: [error: 404 Not Found: The requested URL was not found on the server.  If you entered the URL manually please check your spelling and try again.]
Traceback (most recent call last):
  File "C:\ProgramData\Anaconda3\envs\BI-dashboard\lib\site-packages\flask\app.py", line 1813, in full_dispatch_request
    rv = self.dispatch_request()
  File "C:\ProgramData\Anaconda3\envs\BI-dashboard\lib\site-packages\flask\app.py", line 1791, in dispatch_request
    self.raise_routing_exception(req)
  File "C:\ProgramData\Anaconda3\envs\BI-dashboard\lib\site-packages\flask\app.py", line 1774, in raise_routing_exception
    raise request.routing_exception
  File "C:\ProgramData\Anaconda3\envs\BI-dashboard\lib\site-packages\flask\ctx.py", line 336, in match_request
    self.url_adapter.match(return_rule=True)
  File "C:\ProgramData\Anaconda3\envs\BI-dashboard\lib\site-packages\werkzeug\routing.py", line 1581, in match
    raise NotFound()
werkzeug.exceptions.NotFound: 404 Not Found: The requested URL was not found on the server.  If you entered the URL manually please check your spelling and try again.
2018-10-29 17:23:03,872 - da-service - WARNING - 访问了未知路径: [error: 404 Not Found: The requested URL was not found on the server.  If you entered the URL manually please check your spelling and try again.]
Traceback (most recent call last):
  File "C:\ProgramData\Anaconda3\envs\BI-dashboard\lib\site-packages\flask\app.py", line 1813, in full_dispatch_request
    rv = self.dispatch_request()
  File "C:\ProgramData\Anaconda3\envs\BI-dashboard\lib\site-packages\flask\app.py", line 1791, in dispatch_request
    self.raise_routing_exception(req)
  File "C:\ProgramData\Anaconda3\envs\BI-dashboard\lib\site-packages\flask\app.py", line 1774, in raise_routing_exception
    raise request.routing_exception
  File "C:\ProgramData\Anaconda3\envs\BI-dashboard\lib\site-packages\flask\ctx.py", line 336, in match_request
    self.url_adapter.match(return_rule=True)
  File "C:\ProgramData\Anaconda3\envs\BI-dashboard\lib\site-packages\werkzeug\routing.py", line 1581, in match
    raise NotFound()
werkzeug.exceptions.NotFound: 404 Not Found: The requested URL was not found on the server.  If you entered the URL manually please check your spelling and try again.
2018-10-29 17:23:03,928 - da-service - WARNING - 访问了未知路径: [error: 404 Not Found: The requested URL was not found on the server.  If you entered the URL manually please check your spelling and try again.]
Traceback (most recent call last):
  File "C:\ProgramData\Anaconda3\envs\BI-dashboard\lib\site-packages\flask\app.py", line 1813, in full_dispatch_request
    rv = self.dispatch_request()
  File "C:\ProgramData\Anaconda3\envs\BI-dashboard\lib\site-packages\flask\app.py", line 1791, in dispatch_request
    self.raise_routing_exception(req)
  File "C:\ProgramData\Anaconda3\envs\BI-dashboard\lib\site-packages\flask\app.py", line 1774, in raise_routing_exception
    raise request.routing_exception
  File "C:\ProgramData\Anaconda3\envs\BI-dashboard\lib\site-packages\flask\ctx.py", line 336, in match_request
    self.url_adapter.match(return_rule=True)
  File "C:\ProgramData\Anaconda3\envs\BI-dashboard\lib\site-packages\werkzeug\routing.py", line 1581, in match
    raise NotFound()
werkzeug.exceptions.NotFound: 404 Not Found: The requested URL was not found on the server.  If you entered the URL manually please check your spelling and try again.
2018-10-29 17:23:04,784 - da-service - WARNING - 访问了未知路径: [error: 404 Not Found: The requested URL was not found on the server.  If you entered the URL manually please check your spelling and try again.]
Traceback (most recent call last):
  File "C:\ProgramData\Anaconda3\envs\BI-dashboard\lib\site-packages\flask\app.py", line 1813, in full_dispatch_request
    rv = self.dispatch_request()
  File "C:\ProgramData\Anaconda3\envs\BI-dashboard\lib\site-packages\flask\app.py", line 1791, in dispatch_request
    self.raise_routing_exception(req)
  File "C:\ProgramData\Anaconda3\envs\BI-dashboard\lib\site-packages\flask\app.py", line 1774, in raise_routing_exception
    raise request.routing_exception
  File "C:\ProgramData\Anaconda3\envs\BI-dashboard\lib\site-packages\flask\ctx.py", line 336, in match_request
    self.url_adapter.match(return_rule=True)
  File "C:\ProgramData\Anaconda3\envs\BI-dashboard\lib\site-packages\werkzeug\routing.py", line 1581, in match
    raise NotFound()
werkzeug.exceptions.NotFound: 404 Not Found: The requested URL was not found on the server.  If you entered the URL manually please check your spelling and try again.
2018-10-29 17:23:15,000 - da-service - WARNING - 访问了未知路径: [error: 404 Not Found: The requested URL was not found on the server.  If you entered the URL manually please check your spelling and try again.]
Traceback (most recent call last):
  File "C:\ProgramData\Anaconda3\envs\BI-dashboard\lib\site-packages\flask\app.py", line 1813, in full_dispatch_request
    rv = self.dispatch_request()
  File "C:\ProgramData\Anaconda3\envs\BI-dashboard\lib\site-packages\flask\app.py", line 1799, in dispatch_request
    return self.view_functions[rule.endpoint](**req.view_args)
  File "C:\ProgramData\Anaconda3\envs\BI-dashboard\lib\site-packages\flask\helpers.py", line 976, in send_static_file
    cache_timeout=cache_timeout)
  File "C:\ProgramData\Anaconda3\envs\BI-dashboard\lib\site-packages\flask\helpers.py", line 709, in send_from_directory
    raise NotFound()
werkzeug.exceptions.NotFound: 404 Not Found: The requested URL was not found on the server.  If you entered the URL manually please check your spelling and try again.
2018-10-29 17:28:27,884 - da-service - WARNING - 访问了未知路径: [error: 404 Not Found: The requested URL was not found on the server.  If you entered the URL manually please check your spelling and try again.]
Traceback (most recent call last):
  File "C:\ProgramData\Anaconda3\envs\BI-dashboard\lib\site-packages\flask\app.py", line 1813, in full_dispatch_request
    rv = self.dispatch_request()
  File "C:\ProgramData\Anaconda3\envs\BI-dashboard\lib\site-packages\flask\app.py", line 1791, in dispatch_request
    self.raise_routing_exception(req)
  File "C:\ProgramData\Anaconda3\envs\BI-dashboard\lib\site-packages\flask\app.py", line 1774, in raise_routing_exception
    raise request.routing_exception
  File "C:\ProgramData\Anaconda3\envs\BI-dashboard\lib\site-packages\flask\ctx.py", line 336, in match_request
    self.url_adapter.match(return_rule=True)
  File "C:\ProgramData\Anaconda3\envs\BI-dashboard\lib\site-packages\werkzeug\routing.py", line 1581, in match
    raise NotFound()
werkzeug.exceptions.NotFound: 404 Not Found: The requested URL was not found on the server.  If you entered the URL manually please check your spelling and try again.
2018-10-29 17:28:27,935 - da-service - WARNING - 访问了未知路径: [error: 404 Not Found: The requested URL was not found on the server.  If you entered the URL manually please check your spelling and try again.]
Traceback (most recent call last):
  File "C:\ProgramData\Anaconda3\envs\BI-dashboard\lib\site-packages\flask\app.py", line 1813, in full_dispatch_request
    rv = self.dispatch_request()
  File "C:\ProgramData\Anaconda3\envs\BI-dashboard\lib\site-packages\flask\app.py", line 1791, in dispatch_request
    self.raise_routing_exception(req)
  File "C:\ProgramData\Anaconda3\envs\BI-dashboard\lib\site-packages\flask\app.py", line 1774, in raise_routing_exception
    raise request.routing_exception
  File "C:\ProgramData\Anaconda3\envs\BI-dashboard\lib\site-packages\flask\ctx.py", line 336, in match_request
    self.url_adapter.match(return_rule=True)
  File "C:\ProgramData\Anaconda3\envs\BI-dashboard\lib\site-packages\werkzeug\routing.py", line 1581, in match
    raise NotFound()
werkzeug.exceptions.NotFound: 404 Not Found: The requested URL was not found on the server.  If you entered the URL manually please check your spelling and try again.
2018-10-29 17:28:28,013 - da-service - WARNING - 访问了未知路径: [error: 404 Not Found: The requested URL was not found on the server.  If you entered the URL manually please check your spelling and try again.]
Traceback (most recent call last):
  File "C:\ProgramData\Anaconda3\envs\BI-dashboard\lib\site-packages\flask\app.py", line 1813, in full_dispatch_request
    rv = self.dispatch_request()
  File "C:\ProgramData\Anaconda3\envs\BI-dashboard\lib\site-packages\flask\app.py", line 1799, in dispatch_request
    return self.view_functions[rule.endpoint](**req.view_args)
  File "C:\ProgramData\Anaconda3\envs\BI-dashboard\lib\site-packages\flask\helpers.py", line 976, in send_static_file
    cache_timeout=cache_timeout)
  File "C:\ProgramData\Anaconda3\envs\BI-dashboard\lib\site-packages\flask\helpers.py", line 709, in send_from_directory
    raise NotFound()
werkzeug.exceptions.NotFound: 404 Not Found: The requested URL was not found on the server.  If you entered the URL manually please check your spelling and try again.
2018-10-29 17:28:28,931 - da-service - WARNING - 访问了未知路径: [error: 404 Not Found: The requested URL was not found on the server.  If you entered the URL manually please check your spelling and try again.]
Traceback (most recent call last):
  File "C:\ProgramData\Anaconda3\envs\BI-dashboard\lib\site-packages\flask\app.py", line 1813, in full_dispatch_request
    rv = self.dispatch_request()
  File "C:\ProgramData\Anaconda3\envs\BI-dashboard\lib\site-packages\flask\app.py", line 1791, in dispatch_request
    self.raise_routing_exception(req)
  File "C:\ProgramData\Anaconda3\envs\BI-dashboard\lib\site-packages\flask\app.py", line 1774, in raise_routing_exception
    raise request.routing_exception
  File "C:\ProgramData\Anaconda3\envs\BI-dashboard\lib\site-packages\flask\ctx.py", line 336, in match_request
    self.url_adapter.match(return_rule=True)
  File "C:\ProgramData\Anaconda3\envs\BI-dashboard\lib\site-packages\werkzeug\routing.py", line 1581, in match
    raise NotFound()
werkzeug.exceptions.NotFound: 404 Not Found: The requested URL was not found on the server.  If you entered the URL manually please check your spelling and try again.
2018-10-29 18:09:33,529 - da-service - WARNING - 访问了未知路径: [error: 404 Not Found: The requested URL was not found on the server.  If you entered the URL manually please check your spelling and try again.]
Traceback (most recent call last):
  File "C:\ProgramData\Anaconda3\envs\BI-dashboard\lib\site-packages\flask\app.py", line 1813, in full_dispatch_request
    rv = self.dispatch_request()
  File "C:\ProgramData\Anaconda3\envs\BI-dashboard\lib\site-packages\flask\app.py", line 1791, in dispatch_request
    self.raise_routing_exception(req)
  File "C:\ProgramData\Anaconda3\envs\BI-dashboard\lib\site-packages\flask\app.py", line 1774, in raise_routing_exception
    raise request.routing_exception
  File "C:\ProgramData\Anaconda3\envs\BI-dashboard\lib\site-packages\flask\ctx.py", line 336, in match_request
    self.url_adapter.match(return_rule=True)
  File "C:\ProgramData\Anaconda3\envs\BI-dashboard\lib\site-packages\werkzeug\routing.py", line 1581, in match
    raise NotFound()
werkzeug.exceptions.NotFound: 404 Not Found: The requested URL was not found on the server.  If you entered the URL manually please check your spelling and try again.
2018-10-29 18:09:35,156 - da-service - WARNING - 访问了未知路径: [error: 404 Not Found: The requested URL was not found on the server.  If you entered the URL manually please check your spelling and try again.]
Traceback (most recent call last):
  File "C:\ProgramData\Anaconda3\envs\BI-dashboard\lib\site-packages\flask\app.py", line 1813, in full_dispatch_request
    rv = self.dispatch_request()
  File "C:\ProgramData\Anaconda3\envs\BI-dashboard\lib\site-packages\flask\app.py", line 1791, in dispatch_request
    self.raise_routing_exception(req)
  File "C:\ProgramData\Anaconda3\envs\BI-dashboard\lib\site-packages\flask\app.py", line 1774, in raise_routing_exception
    raise request.routing_exception
  File "C:\ProgramData\Anaconda3\envs\BI-dashboard\lib\site-packages\flask\ctx.py", line 336, in match_request
    self.url_adapter.match(return_rule=True)
  File "C:\ProgramData\Anaconda3\envs\BI-dashboard\lib\site-packages\werkzeug\routing.py", line 1581, in match
    raise NotFound()
werkzeug.exceptions.NotFound: 404 Not Found: The requested URL was not found on the server.  If you entered the URL manually please check your spelling and try again.
2018-10-29 18:09:36,414 - da-service - WARNING - 访问了未知路径: [error: 404 Not Found: The requested URL was not found on the server.  If you entered the URL manually please check your spelling and try again.]
Traceback (most recent call last):
  File "C:\ProgramData\Anaconda3\envs\BI-dashboard\lib\site-packages\flask\app.py", line 1813, in full_dispatch_request
    rv = self.dispatch_request()
  File "C:\ProgramData\Anaconda3\envs\BI-dashboard\lib\site-packages\flask\app.py", line 1791, in dispatch_request
    self.raise_routing_exception(req)
  File "C:\ProgramData\Anaconda3\envs\BI-dashboard\lib\site-packages\flask\app.py", line 1774, in raise_routing_exception
    raise request.routing_exception
  File "C:\ProgramData\Anaconda3\envs\BI-dashboard\lib\site-packages\flask\ctx.py", line 336, in match_request
    self.url_adapter.match(return_rule=True)
  File "C:\ProgramData\Anaconda3\envs\BI-dashboard\lib\site-packages\werkzeug\routing.py", line 1581, in match
    raise NotFound()
werkzeug.exceptions.NotFound: 404 Not Found: The requested URL was not found on the server.  If you entered the URL manually please check your spelling and try again.
2018-10-29 18:10:01,243 - da-service - WARNING - 服务发生异常: [error: Object of type 'generator' is not JSON serializable]
Traceback (most recent call last):
  File "C:\ProgramData\Anaconda3\envs\BI-dashboard\lib\site-packages\flask\app.py", line 1813, in full_dispatch_request
    rv = self.dispatch_request()
  File "C:\ProgramData\Anaconda3\envs\BI-dashboard\lib\site-packages\flask\app.py", line 1799, in dispatch_request
    return self.view_functions[rule.endpoint](**req.view_args)
  File "C:\ProgramData\Anaconda3\envs\BI-dashboard\lib\site-packages\flask_restplus\api.py", line 317, in wrapper
    return self.make_response(data, code, headers=headers)
  File "C:\ProgramData\Anaconda3\envs\BI-dashboard\lib\site-packages\flask_restplus\api.py", line 338, in make_response
    resp = self.representations[mediatype](data, *args, **kwargs)
  File "C:\ProgramData\Anaconda3\envs\BI-dashboard\lib\site-packages\flask_restplus\representations.py", line 22, in output_json
    dumped = dumps(data, **settings) + "\n"
  File "C:\ProgramData\Anaconda3\envs\BI-dashboard\lib\json\__init__.py", line 231, in dumps
    return _default_encoder.encode(obj)
  File "C:\ProgramData\Anaconda3\envs\BI-dashboard\lib\json\encoder.py", line 199, in encode
    chunks = self.iterencode(o, _one_shot=True)
  File "C:\ProgramData\Anaconda3\envs\BI-dashboard\lib\json\encoder.py", line 257, in iterencode
    return _iterencode(o, 0)
  File "C:\ProgramData\Anaconda3\envs\BI-dashboard\lib\json\encoder.py", line 180, in default
    o.__class__.__name__)
TypeError: Object of type 'generator' is not JSON serializable
2018-10-29 18:10:01,270 - da-service - WARNING - 服务发生异常: [error: Object of type 'generator' is not JSON serializable]
Traceback (most recent call last):
  File "C:\ProgramData\Anaconda3\envs\BI-dashboard\lib\site-packages\flask\app.py", line 2292, in wsgi_app
    response = self.full_dispatch_request()
  File "C:\ProgramData\Anaconda3\envs\BI-dashboard\lib\site-packages\flask\app.py", line 1815, in full_dispatch_request
    rv = self.handle_user_exception(e)
  File "C:\ProgramData\Anaconda3\envs\BI-dashboard\lib\site-packages\flask_restplus\api.py", line 557, in error_router
    return original_handler(e)
  File "C:\ProgramData\Anaconda3\envs\BI-dashboard\lib\site-packages\flask\app.py", line 1718, in handle_user_exception
    reraise(exc_type, exc_value, tb)
  File "C:\ProgramData\Anaconda3\envs\BI-dashboard\lib\site-packages\flask\_compat.py", line 35, in reraise
    raise value
  File "C:\ProgramData\Anaconda3\envs\BI-dashboard\lib\site-packages\flask\app.py", line 1813, in full_dispatch_request
    rv = self.dispatch_request()
  File "C:\ProgramData\Anaconda3\envs\BI-dashboard\lib\site-packages\flask\app.py", line 1799, in dispatch_request
    return self.view_functions[rule.endpoint](**req.view_args)
  File "C:\ProgramData\Anaconda3\envs\BI-dashboard\lib\site-packages\flask_restplus\api.py", line 317, in wrapper
    return self.make_response(data, code, headers=headers)
  File "C:\ProgramData\Anaconda3\envs\BI-dashboard\lib\site-packages\flask_restplus\api.py", line 338, in make_response
    resp = self.representations[mediatype](data, *args, **kwargs)
  File "C:\ProgramData\Anaconda3\envs\BI-dashboard\lib\site-packages\flask_restplus\representations.py", line 22, in output_json
    dumped = dumps(data, **settings) + "\n"
  File "C:\ProgramData\Anaconda3\envs\BI-dashboard\lib\json\__init__.py", line 231, in dumps
    return _default_encoder.encode(obj)
  File "C:\ProgramData\Anaconda3\envs\BI-dashboard\lib\json\encoder.py", line 199, in encode
    chunks = self.iterencode(o, _one_shot=True)
  File "C:\ProgramData\Anaconda3\envs\BI-dashboard\lib\json\encoder.py", line 257, in iterencode
    return _iterencode(o, 0)
  File "C:\ProgramData\Anaconda3\envs\BI-dashboard\lib\json\encoder.py", line 180, in default
    o.__class__.__name__)
TypeError: Object of type 'generator' is not JSON serializable
2018-10-29 18:10:01,276 - da-service - WARNING - 内部服务发生异常: [error: Object of type 'generator' is not JSON serializable]
Traceback (most recent call last):
  File "C:\ProgramData\Anaconda3\envs\BI-dashboard\lib\site-packages\flask\app.py", line 2292, in wsgi_app
    response = self.full_dispatch_request()
  File "C:\ProgramData\Anaconda3\envs\BI-dashboard\lib\site-packages\flask\app.py", line 1815, in full_dispatch_request
    rv = self.handle_user_exception(e)
  File "C:\ProgramData\Anaconda3\envs\BI-dashboard\lib\site-packages\flask_restplus\api.py", line 557, in error_router
    return original_handler(e)
  File "C:\ProgramData\Anaconda3\envs\BI-dashboard\lib\site-packages\flask\app.py", line 1718, in handle_user_exception
    reraise(exc_type, exc_value, tb)
  File "C:\ProgramData\Anaconda3\envs\BI-dashboard\lib\site-packages\flask\_compat.py", line 35, in reraise
    raise value
  File "C:\ProgramData\Anaconda3\envs\BI-dashboard\lib\site-packages\flask\app.py", line 1813, in full_dispatch_request
    rv = self.dispatch_request()
  File "C:\ProgramData\Anaconda3\envs\BI-dashboard\lib\site-packages\flask\app.py", line 1799, in dispatch_request
    return self.view_functions[rule.endpoint](**req.view_args)
  File "C:\ProgramData\Anaconda3\envs\BI-dashboard\lib\site-packages\flask_restplus\api.py", line 317, in wrapper
    return self.make_response(data, code, headers=headers)
  File "C:\ProgramData\Anaconda3\envs\BI-dashboard\lib\site-packages\flask_restplus\api.py", line 338, in make_response
    resp = self.representations[mediatype](data, *args, **kwargs)
  File "C:\ProgramData\Anaconda3\envs\BI-dashboard\lib\site-packages\flask_restplus\representations.py", line 22, in output_json
    dumped = dumps(data, **settings) + "\n"
  File "C:\ProgramData\Anaconda3\envs\BI-dashboard\lib\json\__init__.py", line 231, in dumps
    return _default_encoder.encode(obj)
  File "C:\ProgramData\Anaconda3\envs\BI-dashboard\lib\json\encoder.py", line 199, in encode
    chunks = self.iterencode(o, _one_shot=True)
  File "C:\ProgramData\Anaconda3\envs\BI-dashboard\lib\json\encoder.py", line 257, in iterencode
    return _iterencode(o, 0)
  File "C:\ProgramData\Anaconda3\envs\BI-dashboard\lib\json\encoder.py", line 180, in default
    o.__class__.__name__)
TypeError: Object of type 'generator' is not JSON serializable
2018-10-29 19:32:22,923 - da-service - WARNING - 访问了未知路径: [error: 404 Not Found: The requested URL was not found on the server.  If you entered the URL manually please check your spelling and try again.]
Traceback (most recent call last):
  File "C:\ProgramData\Anaconda3\envs\BI-dashboard\lib\site-packages\flask\app.py", line 1813, in full_dispatch_request
    rv = self.dispatch_request()
  File "C:\ProgramData\Anaconda3\envs\BI-dashboard\lib\site-packages\flask\app.py", line 1791, in dispatch_request
    self.raise_routing_exception(req)
  File "C:\ProgramData\Anaconda3\envs\BI-dashboard\lib\site-packages\flask\app.py", line 1774, in raise_routing_exception
    raise request.routing_exception
  File "C:\ProgramData\Anaconda3\envs\BI-dashboard\lib\site-packages\flask\ctx.py", line 336, in match_request
    self.url_adapter.match(return_rule=True)
  File "C:\ProgramData\Anaconda3\envs\BI-dashboard\lib\site-packages\werkzeug\routing.py", line 1581, in match
    raise NotFound()
werkzeug.exceptions.NotFound: 404 Not Found: The requested URL was not found on the server.  If you entered the URL manually please check your spelling and try again.
2018-10-29 19:32:22,960 - da-service - WARNING - 访问了未知路径: [error: 404 Not Found: The requested URL was not found on the server.  If you entered the URL manually please check your spelling and try again.]
Traceback (most recent call last):
  File "C:\ProgramData\Anaconda3\envs\BI-dashboard\lib\site-packages\flask\app.py", line 1813, in full_dispatch_request
    rv = self.dispatch_request()
  File "C:\ProgramData\Anaconda3\envs\BI-dashboard\lib\site-packages\flask\app.py", line 1791, in dispatch_request
    self.raise_routing_exception(req)
  File "C:\ProgramData\Anaconda3\envs\BI-dashboard\lib\site-packages\flask\app.py", line 1774, in raise_routing_exception
    raise request.routing_exception
  File "C:\ProgramData\Anaconda3\envs\BI-dashboard\lib\site-packages\flask\ctx.py", line 336, in match_request
    self.url_adapter.match(return_rule=True)
  File "C:\ProgramData\Anaconda3\envs\BI-dashboard\lib\site-packages\werkzeug\routing.py", line 1581, in match
    raise NotFound()
werkzeug.exceptions.NotFound: 404 Not Found: The requested URL was not found on the server.  If you entered the URL manually please check your spelling and try again.
2018-10-29 19:32:24,085 - da-service - WARNING - 访问了未知路径: [error: 404 Not Found: The requested URL was not found on the server.  If you entered the URL manually please check your spelling and try again.]
Traceback (most recent call last):
  File "C:\ProgramData\Anaconda3\envs\BI-dashboard\lib\site-packages\flask\app.py", line 1813, in full_dispatch_request
    rv = self.dispatch_request()
  File "C:\ProgramData\Anaconda3\envs\BI-dashboard\lib\site-packages\flask\app.py", line 1791, in dispatch_request
    self.raise_routing_exception(req)
  File "C:\ProgramData\Anaconda3\envs\BI-dashboard\lib\site-packages\flask\app.py", line 1774, in raise_routing_exception
    raise request.routing_exception
  File "C:\ProgramData\Anaconda3\envs\BI-dashboard\lib\site-packages\flask\ctx.py", line 336, in match_request
    self.url_adapter.match(return_rule=True)
  File "C:\ProgramData\Anaconda3\envs\BI-dashboard\lib\site-packages\werkzeug\routing.py", line 1581, in match
    raise NotFound()
werkzeug.exceptions.NotFound: 404 Not Found: The requested URL was not found on the server.  If you entered the URL manually please check your spelling and try again.
2018-10-29 19:32:28,457 - da-service - WARNING - 访问了未知路径: [error: 404 Not Found: The requested URL was not found on the server.  If you entered the URL manually please check your spelling and try again.]
Traceback (most recent call last):
  File "C:\ProgramData\Anaconda3\envs\BI-dashboard\lib\site-packages\flask\app.py", line 1813, in full_dispatch_request
    rv = self.dispatch_request()
  File "C:\ProgramData\Anaconda3\envs\BI-dashboard\lib\site-packages\flask\app.py", line 1799, in dispatch_request
    return self.view_functions[rule.endpoint](**req.view_args)
  File "C:\ProgramData\Anaconda3\envs\BI-dashboard\lib\site-packages\flask\helpers.py", line 976, in send_static_file
    cache_timeout=cache_timeout)
  File "C:\ProgramData\Anaconda3\envs\BI-dashboard\lib\site-packages\flask\helpers.py", line 709, in send_from_directory
    raise NotFound()
werkzeug.exceptions.NotFound: 404 Not Found: The requested URL was not found on the server.  If you entered the URL manually please check your spelling and try again.
2018-10-29 19:34:32,319 - da-service - WARNING - 访问了未知路径: [error: 404 Not Found: The requested URL was not found on the server.  If you entered the URL manually please check your spelling and try again.]
Traceback (most recent call last):
  File "C:\ProgramData\Anaconda3\envs\BI-dashboard\lib\site-packages\flask\app.py", line 1813, in full_dispatch_request
    rv = self.dispatch_request()
  File "C:\ProgramData\Anaconda3\envs\BI-dashboard\lib\site-packages\flask\app.py", line 1799, in dispatch_request
    return self.view_functions[rule.endpoint](**req.view_args)
  File "C:\ProgramData\Anaconda3\envs\BI-dashboard\lib\site-packages\flask\helpers.py", line 976, in send_static_file
    cache_timeout=cache_timeout)
  File "C:\ProgramData\Anaconda3\envs\BI-dashboard\lib\site-packages\flask\helpers.py", line 709, in send_from_directory
    raise NotFound()
werkzeug.exceptions.NotFound: 404 Not Found: The requested URL was not found on the server.  If you entered the URL manually please check your spelling and try again.
2018-10-29 19:34:39,358 - da-service - WARNING - 访问了未知路径: [error: 404 Not Found: The requested URL was not found on the server.  If you entered the URL manually please check your spelling and try again.]
Traceback (most recent call last):
  File "C:\ProgramData\Anaconda3\envs\BI-dashboard\lib\site-packages\flask\app.py", line 1813, in full_dispatch_request
    rv = self.dispatch_request()
  File "C:\ProgramData\Anaconda3\envs\BI-dashboard\lib\site-packages\flask\app.py", line 1791, in dispatch_request
    self.raise_routing_exception(req)
  File "C:\ProgramData\Anaconda3\envs\BI-dashboard\lib\site-packages\flask\app.py", line 1774, in raise_routing_exception
    raise request.routing_exception
  File "C:\ProgramData\Anaconda3\envs\BI-dashboard\lib\site-packages\flask\ctx.py", line 336, in match_request
    self.url_adapter.match(return_rule=True)
  File "C:\ProgramData\Anaconda3\envs\BI-dashboard\lib\site-packages\werkzeug\routing.py", line 1581, in match
    raise NotFound()
werkzeug.exceptions.NotFound: 404 Not Found: The requested URL was not found on the server.  If you entered the URL manually please check your spelling and try again.
2018-10-30 09:57:32,444 - da-service - WARNING - 访问了未知路径: [error: 404 Not Found: The requested URL was not found on the server.  If you entered the URL manually please check your spelling and try again.]
Traceback (most recent call last):
  File "C:\ProgramData\Anaconda3\envs\BI-dashboard\lib\site-packages\flask\app.py", line 1813, in full_dispatch_request
    rv = self.dispatch_request()
  File "C:\ProgramData\Anaconda3\envs\BI-dashboard\lib\site-packages\flask\app.py", line 1791, in dispatch_request
    self.raise_routing_exception(req)
  File "C:\ProgramData\Anaconda3\envs\BI-dashboard\lib\site-packages\flask\app.py", line 1774, in raise_routing_exception
    raise request.routing_exception
  File "C:\ProgramData\Anaconda3\envs\BI-dashboard\lib\site-packages\flask\ctx.py", line 336, in match_request
    self.url_adapter.match(return_rule=True)
  File "C:\ProgramData\Anaconda3\envs\BI-dashboard\lib\site-packages\werkzeug\routing.py", line 1581, in match
    raise NotFound()
werkzeug.exceptions.NotFound: 404 Not Found: The requested URL was not found on the server.  If you entered the URL manually please check your spelling and try again.
2018-10-30 09:57:37,606 - da-service - WARNING - 访问了未知路径: [error: 404 Not Found: The requested URL was not found on the server.  If you entered the URL manually please check your spelling and try again.]
Traceback (most recent call last):
  File "C:\ProgramData\Anaconda3\envs\BI-dashboard\lib\site-packages\flask\app.py", line 1813, in full_dispatch_request
    rv = self.dispatch_request()
  File "C:\ProgramData\Anaconda3\envs\BI-dashboard\lib\site-packages\flask\app.py", line 1791, in dispatch_request
    self.raise_routing_exception(req)
  File "C:\ProgramData\Anaconda3\envs\BI-dashboard\lib\site-packages\flask\app.py", line 1774, in raise_routing_exception
    raise request.routing_exception
  File "C:\ProgramData\Anaconda3\envs\BI-dashboard\lib\site-packages\flask\ctx.py", line 336, in match_request
    self.url_adapter.match(return_rule=True)
  File "C:\ProgramData\Anaconda3\envs\BI-dashboard\lib\site-packages\werkzeug\routing.py", line 1581, in match
    raise NotFound()
werkzeug.exceptions.NotFound: 404 Not Found: The requested URL was not found on the server.  If you entered the URL manually please check your spelling and try again.
2018-10-30 09:57:39,717 - da-service - WARNING - 访问了未知路径: [error: 404 Not Found: The requested URL was not found on the server.  If you entered the URL manually please check your spelling and try again.]
Traceback (most recent call last):
  File "C:\ProgramData\Anaconda3\envs\BI-dashboard\lib\site-packages\flask\app.py", line 1813, in full_dispatch_request
    rv = self.dispatch_request()
  File "C:\ProgramData\Anaconda3\envs\BI-dashboard\lib\site-packages\flask\app.py", line 1791, in dispatch_request
    self.raise_routing_exception(req)
  File "C:\ProgramData\Anaconda3\envs\BI-dashboard\lib\site-packages\flask\app.py", line 1774, in raise_routing_exception
    raise request.routing_exception
  File "C:\ProgramData\Anaconda3\envs\BI-dashboard\lib\site-packages\flask\ctx.py", line 336, in match_request
    self.url_adapter.match(return_rule=True)
  File "C:\ProgramData\Anaconda3\envs\BI-dashboard\lib\site-packages\werkzeug\routing.py", line 1581, in match
    raise NotFound()
werkzeug.exceptions.NotFound: 404 Not Found: The requested URL was not found on the server.  If you entered the URL manually please check your spelling and try again.
2018-10-30 09:57:39,748 - da-service - WARNING - 访问了未知路径: [error: 404 Not Found: The requested URL was not found on the server.  If you entered the URL manually please check your spelling and try again.]
Traceback (most recent call last):
  File "C:\ProgramData\Anaconda3\envs\BI-dashboard\lib\site-packages\flask\app.py", line 1813, in full_dispatch_request
    rv = self.dispatch_request()
  File "C:\ProgramData\Anaconda3\envs\BI-dashboard\lib\site-packages\flask\app.py", line 1791, in dispatch_request
    self.raise_routing_exception(req)
  File "C:\ProgramData\Anaconda3\envs\BI-dashboard\lib\site-packages\flask\app.py", line 1774, in raise_routing_exception
    raise request.routing_exception
  File "C:\ProgramData\Anaconda3\envs\BI-dashboard\lib\site-packages\flask\ctx.py", line 336, in match_request
    self.url_adapter.match(return_rule=True)
  File "C:\ProgramData\Anaconda3\envs\BI-dashboard\lib\site-packages\werkzeug\routing.py", line 1581, in match
    raise NotFound()
werkzeug.exceptions.NotFound: 404 Not Found: The requested URL was not found on the server.  If you entered the URL manually please check your spelling and try again.
2018-10-30 09:57:40,684 - da-service - WARNING - 访问了未知路径: [error: 404 Not Found: The requested URL was not found on the server.  If you entered the URL manually please check your spelling and try again.]
Traceback (most recent call last):
  File "C:\ProgramData\Anaconda3\envs\BI-dashboard\lib\site-packages\flask\app.py", line 1813, in full_dispatch_request
    rv = self.dispatch_request()
  File "C:\ProgramData\Anaconda3\envs\BI-dashboard\lib\site-packages\flask\app.py", line 1791, in dispatch_request
    self.raise_routing_exception(req)
  File "C:\ProgramData\Anaconda3\envs\BI-dashboard\lib\site-packages\flask\app.py", line 1774, in raise_routing_exception
    raise request.routing_exception
  File "C:\ProgramData\Anaconda3\envs\BI-dashboard\lib\site-packages\flask\ctx.py", line 336, in match_request
    self.url_adapter.match(return_rule=True)
  File "C:\ProgramData\Anaconda3\envs\BI-dashboard\lib\site-packages\werkzeug\routing.py", line 1581, in match
    raise NotFound()
werkzeug.exceptions.NotFound: 404 Not Found: The requested URL was not found on the server.  If you entered the URL manually please check your spelling and try again.
2018-10-30 09:59:52,873 - da-service - WARNING - 访问了未知路径: [error: 404 Not Found: The requested URL was not found on the server.  If you entered the URL manually please check your spelling and try again.]
Traceback (most recent call last):
  File "C:\ProgramData\Anaconda3\envs\BI-dashboard\lib\site-packages\flask\app.py", line 1813, in full_dispatch_request
    rv = self.dispatch_request()
  File "C:\ProgramData\Anaconda3\envs\BI-dashboard\lib\site-packages\flask\app.py", line 1791, in dispatch_request
    self.raise_routing_exception(req)
  File "C:\ProgramData\Anaconda3\envs\BI-dashboard\lib\site-packages\flask\app.py", line 1774, in raise_routing_exception
    raise request.routing_exception
  File "C:\ProgramData\Anaconda3\envs\BI-dashboard\lib\site-packages\flask\ctx.py", line 336, in match_request
    self.url_adapter.match(return_rule=True)
  File "C:\ProgramData\Anaconda3\envs\BI-dashboard\lib\site-packages\werkzeug\routing.py", line 1581, in match
    raise NotFound()
werkzeug.exceptions.NotFound: 404 Not Found: The requested URL was not found on the server.  If you entered the URL manually please check your spelling and try again.
2018-10-30 09:59:52,907 - da-service - WARNING - 访问了未知路径: [error: 404 Not Found: The requested URL was not found on the server.  If you entered the URL manually please check your spelling and try again.]
Traceback (most recent call last):
  File "C:\ProgramData\Anaconda3\envs\BI-dashboard\lib\site-packages\flask\app.py", line 1813, in full_dispatch_request
    rv = self.dispatch_request()
  File "C:\ProgramData\Anaconda3\envs\BI-dashboard\lib\site-packages\flask\app.py", line 1791, in dispatch_request
    self.raise_routing_exception(req)
  File "C:\ProgramData\Anaconda3\envs\BI-dashboard\lib\site-packages\flask\app.py", line 1774, in raise_routing_exception
    raise request.routing_exception
  File "C:\ProgramData\Anaconda3\envs\BI-dashboard\lib\site-packages\flask\ctx.py", line 336, in match_request
    self.url_adapter.match(return_rule=True)
  File "C:\ProgramData\Anaconda3\envs\BI-dashboard\lib\site-packages\werkzeug\routing.py", line 1581, in match
    raise NotFound()
werkzeug.exceptions.NotFound: 404 Not Found: The requested URL was not found on the server.  If you entered the URL manually please check your spelling and try again.
2018-10-30 09:59:53,877 - da-service - WARNING - 访问了未知路径: [error: 404 Not Found: The requested URL was not found on the server.  If you entered the URL manually please check your spelling and try again.]
Traceback (most recent call last):
  File "C:\ProgramData\Anaconda3\envs\BI-dashboard\lib\site-packages\flask\app.py", line 1813, in full_dispatch_request
    rv = self.dispatch_request()
  File "C:\ProgramData\Anaconda3\envs\BI-dashboard\lib\site-packages\flask\app.py", line 1791, in dispatch_request
    self.raise_routing_exception(req)
  File "C:\ProgramData\Anaconda3\envs\BI-dashboard\lib\site-packages\flask\app.py", line 1774, in raise_routing_exception
    raise request.routing_exception
  File "C:\ProgramData\Anaconda3\envs\BI-dashboard\lib\site-packages\flask\ctx.py", line 336, in match_request
    self.url_adapter.match(return_rule=True)
  File "C:\ProgramData\Anaconda3\envs\BI-dashboard\lib\site-packages\werkzeug\routing.py", line 1581, in match
    raise NotFound()
werkzeug.exceptions.NotFound: 404 Not Found: The requested URL was not found on the server.  If you entered the URL manually please check your spelling and try again.
2018-10-30 10:02:46,275 - da-service - WARNING - 访问了未知路径: [error: 404 Not Found: The requested URL was not found on the server.  If you entered the URL manually please check your spelling and try again.]
Traceback (most recent call last):
  File "C:\ProgramData\Anaconda3\envs\BI-dashboard\lib\site-packages\flask\app.py", line 1813, in full_dispatch_request
    rv = self.dispatch_request()
  File "C:\ProgramData\Anaconda3\envs\BI-dashboard\lib\site-packages\flask\app.py", line 1791, in dispatch_request
    self.raise_routing_exception(req)
  File "C:\ProgramData\Anaconda3\envs\BI-dashboard\lib\site-packages\flask\app.py", line 1774, in raise_routing_exception
    raise request.routing_exception
  File "C:\ProgramData\Anaconda3\envs\BI-dashboard\lib\site-packages\flask\ctx.py", line 336, in match_request
    self.url_adapter.match(return_rule=True)
  File "C:\ProgramData\Anaconda3\envs\BI-dashboard\lib\site-packages\werkzeug\routing.py", line 1581, in match
    raise NotFound()
werkzeug.exceptions.NotFound: 404 Not Found: The requested URL was not found on the server.  If you entered the URL manually please check your spelling and try again.
2018-10-30 10:02:46,323 - da-service - WARNING - 访问了未知路径: [error: 404 Not Found: The requested URL was not found on the server.  If you entered the URL manually please check your spelling and try again.]
Traceback (most recent call last):
  File "C:\ProgramData\Anaconda3\envs\BI-dashboard\lib\site-packages\flask\app.py", line 1813, in full_dispatch_request
    rv = self.dispatch_request()
  File "C:\ProgramData\Anaconda3\envs\BI-dashboard\lib\site-packages\flask\app.py", line 1791, in dispatch_request
    self.raise_routing_exception(req)
  File "C:\ProgramData\Anaconda3\envs\BI-dashboard\lib\site-packages\flask\app.py", line 1774, in raise_routing_exception
    raise request.routing_exception
  File "C:\ProgramData\Anaconda3\envs\BI-dashboard\lib\site-packages\flask\ctx.py", line 336, in match_request
    self.url_adapter.match(return_rule=True)
  File "C:\ProgramData\Anaconda3\envs\BI-dashboard\lib\site-packages\werkzeug\routing.py", line 1581, in match
    raise NotFound()
werkzeug.exceptions.NotFound: 404 Not Found: The requested URL was not found on the server.  If you entered the URL manually please check your spelling and try again.
2018-10-30 10:02:47,473 - da-service - WARNING - 访问了未知路径: [error: 404 Not Found: The requested URL was not found on the server.  If you entered the URL manually please check your spelling and try again.]
Traceback (most recent call last):
  File "C:\ProgramData\Anaconda3\envs\BI-dashboard\lib\site-packages\flask\app.py", line 1813, in full_dispatch_request
    rv = self.dispatch_request()
  File "C:\ProgramData\Anaconda3\envs\BI-dashboard\lib\site-packages\flask\app.py", line 1791, in dispatch_request
    self.raise_routing_exception(req)
  File "C:\ProgramData\Anaconda3\envs\BI-dashboard\lib\site-packages\flask\app.py", line 1774, in raise_routing_exception
    raise request.routing_exception
  File "C:\ProgramData\Anaconda3\envs\BI-dashboard\lib\site-packages\flask\ctx.py", line 336, in match_request
    self.url_adapter.match(return_rule=True)
  File "C:\ProgramData\Anaconda3\envs\BI-dashboard\lib\site-packages\werkzeug\routing.py", line 1581, in match
    raise NotFound()
werkzeug.exceptions.NotFound: 404 Not Found: The requested URL was not found on the server.  If you entered the URL manually please check your spelling and try again.
2018-10-30 10:05:03,826 - da-service - WARNING - 访问了未知路径: [error: 404 Not Found: The requested URL was not found on the server.  If you entered the URL manually please check your spelling and try again.]
Traceback (most recent call last):
  File "C:\ProgramData\Anaconda3\envs\BI-dashboard\lib\site-packages\flask\app.py", line 1813, in full_dispatch_request
    rv = self.dispatch_request()
  File "C:\ProgramData\Anaconda3\envs\BI-dashboard\lib\site-packages\flask\app.py", line 1791, in dispatch_request
    self.raise_routing_exception(req)
  File "C:\ProgramData\Anaconda3\envs\BI-dashboard\lib\site-packages\flask\app.py", line 1774, in raise_routing_exception
    raise request.routing_exception
  File "C:\ProgramData\Anaconda3\envs\BI-dashboard\lib\site-packages\flask\ctx.py", line 336, in match_request
    self.url_adapter.match(return_rule=True)
  File "C:\ProgramData\Anaconda3\envs\BI-dashboard\lib\site-packages\werkzeug\routing.py", line 1581, in match
    raise NotFound()
werkzeug.exceptions.NotFound: 404 Not Found: The requested URL was not found on the server.  If you entered the URL manually please check your spelling and try again.
2018-10-30 10:05:03,831 - da-service - WARNING - 访问了未知路径: [error: 404 Not Found: The requested URL was not found on the server.  If you entered the URL manually please check your spelling and try again.]
Traceback (most recent call last):
  File "C:\ProgramData\Anaconda3\envs\BI-dashboard\lib\site-packages\flask\app.py", line 1813, in full_dispatch_request
    rv = self.dispatch_request()
  File "C:\ProgramData\Anaconda3\envs\BI-dashboard\lib\site-packages\flask\app.py", line 1791, in dispatch_request
    self.raise_routing_exception(req)
  File "C:\ProgramData\Anaconda3\envs\BI-dashboard\lib\site-packages\flask\app.py", line 1774, in raise_routing_exception
    raise request.routing_exception
  File "C:\ProgramData\Anaconda3\envs\BI-dashboard\lib\site-packages\flask\ctx.py", line 336, in match_request
    self.url_adapter.match(return_rule=True)
  File "C:\ProgramData\Anaconda3\envs\BI-dashboard\lib\site-packages\werkzeug\routing.py", line 1581, in match
    raise NotFound()
werkzeug.exceptions.NotFound: 404 Not Found: The requested URL was not found on the server.  If you entered the URL manually please check your spelling and try again.
2018-10-30 10:07:23,762 - da-service - WARNING - 访问了未知路径: [error: 404 Not Found: The requested URL was not found on the server.  If you entered the URL manually please check your spelling and try again.]
Traceback (most recent call last):
  File "C:\ProgramData\Anaconda3\envs\BI-dashboard\lib\site-packages\flask\app.py", line 1813, in full_dispatch_request
    rv = self.dispatch_request()
  File "C:\ProgramData\Anaconda3\envs\BI-dashboard\lib\site-packages\flask\app.py", line 1799, in dispatch_request
    return self.view_functions[rule.endpoint](**req.view_args)
  File "C:\ProgramData\Anaconda3\envs\BI-dashboard\lib\site-packages\flask\helpers.py", line 976, in send_static_file
    cache_timeout=cache_timeout)
  File "C:\ProgramData\Anaconda3\envs\BI-dashboard\lib\site-packages\flask\helpers.py", line 709, in send_from_directory
    raise NotFound()
werkzeug.exceptions.NotFound: 404 Not Found: The requested URL was not found on the server.  If you entered the URL manually please check your spelling and try again.
2018-10-30 10:07:35,230 - da-service - WARNING - 访问了未知路径: [error: 404 Not Found: The requested URL was not found on the server.  If you entered the URL manually please check your spelling and try again.]
Traceback (most recent call last):
  File "C:\ProgramData\Anaconda3\envs\BI-dashboard\lib\site-packages\flask\app.py", line 1813, in full_dispatch_request
    rv = self.dispatch_request()
  File "C:\ProgramData\Anaconda3\envs\BI-dashboard\lib\site-packages\flask\app.py", line 1791, in dispatch_request
    self.raise_routing_exception(req)
  File "C:\ProgramData\Anaconda3\envs\BI-dashboard\lib\site-packages\flask\app.py", line 1774, in raise_routing_exception
    raise request.routing_exception
  File "C:\ProgramData\Anaconda3\envs\BI-dashboard\lib\site-packages\flask\ctx.py", line 336, in match_request
    self.url_adapter.match(return_rule=True)
  File "C:\ProgramData\Anaconda3\envs\BI-dashboard\lib\site-packages\werkzeug\routing.py", line 1581, in match
    raise NotFound()
werkzeug.exceptions.NotFound: 404 Not Found: The requested URL was not found on the server.  If you entered the URL manually please check your spelling and try again.
2018-10-30 10:07:46,762 - da-service - WARNING - 访问了未知路径: [error: 404 Not Found: The requested URL was not found on the server.  If you entered the URL manually please check your spelling and try again.]
Traceback (most recent call last):
  File "C:\ProgramData\Anaconda3\envs\BI-dashboard\lib\site-packages\flask\app.py", line 1813, in full_dispatch_request
    rv = self.dispatch_request()
  File "C:\ProgramData\Anaconda3\envs\BI-dashboard\lib\site-packages\flask\app.py", line 1791, in dispatch_request
    self.raise_routing_exception(req)
  File "C:\ProgramData\Anaconda3\envs\BI-dashboard\lib\site-packages\flask\app.py", line 1774, in raise_routing_exception
    raise request.routing_exception
  File "C:\ProgramData\Anaconda3\envs\BI-dashboard\lib\site-packages\flask\ctx.py", line 336, in match_request
    self.url_adapter.match(return_rule=True)
  File "C:\ProgramData\Anaconda3\envs\BI-dashboard\lib\site-packages\werkzeug\routing.py", line 1581, in match
    raise NotFound()
werkzeug.exceptions.NotFound: 404 Not Found: The requested URL was not found on the server.  If you entered the URL manually please check your spelling and try again.
2018-10-30 10:07:46,802 - da-service - WARNING - 访问了未知路径: [error: 404 Not Found: The requested URL was not found on the server.  If you entered the URL manually please check your spelling and try again.]
Traceback (most recent call last):
  File "C:\ProgramData\Anaconda3\envs\BI-dashboard\lib\site-packages\flask\app.py", line 1813, in full_dispatch_request
    rv = self.dispatch_request()
  File "C:\ProgramData\Anaconda3\envs\BI-dashboard\lib\site-packages\flask\app.py", line 1791, in dispatch_request
    self.raise_routing_exception(req)
  File "C:\ProgramData\Anaconda3\envs\BI-dashboard\lib\site-packages\flask\app.py", line 1774, in raise_routing_exception
    raise request.routing_exception
  File "C:\ProgramData\Anaconda3\envs\BI-dashboard\lib\site-packages\flask\ctx.py", line 336, in match_request
    self.url_adapter.match(return_rule=True)
  File "C:\ProgramData\Anaconda3\envs\BI-dashboard\lib\site-packages\werkzeug\routing.py", line 1581, in match
    raise NotFound()
werkzeug.exceptions.NotFound: 404 Not Found: The requested URL was not found on the server.  If you entered the URL manually please check your spelling and try again.
2018-10-30 10:07:52,163 - da-service - WARNING - 访问了未知路径: [error: 404 Not Found: The requested URL was not found on the server.  If you entered the URL manually please check your spelling and try again.]
Traceback (most recent call last):
  File "C:\ProgramData\Anaconda3\envs\BI-dashboard\lib\site-packages\flask\app.py", line 1813, in full_dispatch_request
    rv = self.dispatch_request()
  File "C:\ProgramData\Anaconda3\envs\BI-dashboard\lib\site-packages\flask\app.py", line 1799, in dispatch_request
    return self.view_functions[rule.endpoint](**req.view_args)
  File "C:\ProgramData\Anaconda3\envs\BI-dashboard\lib\site-packages\flask\helpers.py", line 976, in send_static_file
    cache_timeout=cache_timeout)
  File "C:\ProgramData\Anaconda3\envs\BI-dashboard\lib\site-packages\flask\helpers.py", line 709, in send_from_directory
    raise NotFound()
werkzeug.exceptions.NotFound: 404 Not Found: The requested URL was not found on the server.  If you entered the URL manually please check your spelling and try again.
2018-10-30 10:07:58,336 - da-service - WARNING - 访问了未知路径: [error: 404 Not Found: The requested URL was not found on the server.  If you entered the URL manually please check your spelling and try again.]
Traceback (most recent call last):
  File "C:\ProgramData\Anaconda3\envs\BI-dashboard\lib\site-packages\flask\app.py", line 1813, in full_dispatch_request
    rv = self.dispatch_request()
  File "C:\ProgramData\Anaconda3\envs\BI-dashboard\lib\site-packages\flask\app.py", line 1791, in dispatch_request
    self.raise_routing_exception(req)
  File "C:\ProgramData\Anaconda3\envs\BI-dashboard\lib\site-packages\flask\app.py", line 1774, in raise_routing_exception
    raise request.routing_exception
  File "C:\ProgramData\Anaconda3\envs\BI-dashboard\lib\site-packages\flask\ctx.py", line 336, in match_request
    self.url_adapter.match(return_rule=True)
  File "C:\ProgramData\Anaconda3\envs\BI-dashboard\lib\site-packages\werkzeug\routing.py", line 1581, in match
    raise NotFound()
werkzeug.exceptions.NotFound: 404 Not Found: The requested URL was not found on the server.  If you entered the URL manually please check your spelling and try again.
2018-10-30 10:09:58,418 - da-service - WARNING - 访问了未知路径: [error: 404 Not Found: The requested URL was not found on the server.  If you entered the URL manually please check your spelling and try again.]
Traceback (most recent call last):
  File "C:\ProgramData\Anaconda3\envs\BI-dashboard\lib\site-packages\flask\app.py", line 1813, in full_dispatch_request
    rv = self.dispatch_request()
  File "C:\ProgramData\Anaconda3\envs\BI-dashboard\lib\site-packages\flask\app.py", line 1799, in dispatch_request
    return self.view_functions[rule.endpoint](**req.view_args)
  File "C:\ProgramData\Anaconda3\envs\BI-dashboard\lib\site-packages\flask\helpers.py", line 976, in send_static_file
    cache_timeout=cache_timeout)
  File "C:\ProgramData\Anaconda3\envs\BI-dashboard\lib\site-packages\flask\helpers.py", line 709, in send_from_directory
    raise NotFound()
werkzeug.exceptions.NotFound: 404 Not Found: The requested URL was not found on the server.  If you entered the URL manually please check your spelling and try again.
2018-10-30 10:19:22,149 - da-service - WARNING - 访问了未知路径: [error: 404 Not Found: The requested URL was not found on the server.  If you entered the URL manually please check your spelling and try again.]
Traceback (most recent call last):
  File "C:\ProgramData\Anaconda3\envs\BI-dashboard\lib\site-packages\flask\app.py", line 1813, in full_dispatch_request
    rv = self.dispatch_request()
  File "C:\ProgramData\Anaconda3\envs\BI-dashboard\lib\site-packages\flask\app.py", line 1791, in dispatch_request
    self.raise_routing_exception(req)
  File "C:\ProgramData\Anaconda3\envs\BI-dashboard\lib\site-packages\flask\app.py", line 1774, in raise_routing_exception
    raise request.routing_exception
  File "C:\ProgramData\Anaconda3\envs\BI-dashboard\lib\site-packages\flask\ctx.py", line 336, in match_request
    self.url_adapter.match(return_rule=True)
  File "C:\ProgramData\Anaconda3\envs\BI-dashboard\lib\site-packages\werkzeug\routing.py", line 1581, in match
    raise NotFound()
werkzeug.exceptions.NotFound: 404 Not Found: The requested URL was not found on the server.  If you entered the URL manually please check your spelling and try again.
2018-10-30 10:19:22,215 - da-service - WARNING - 访问了未知路径: [error: 404 Not Found: The requested URL was not found on the server.  If you entered the URL manually please check your spelling and try again.]
Traceback (most recent call last):
  File "C:\ProgramData\Anaconda3\envs\BI-dashboard\lib\site-packages\flask\app.py", line 1813, in full_dispatch_request
    rv = self.dispatch_request()
  File "C:\ProgramData\Anaconda3\envs\BI-dashboard\lib\site-packages\flask\app.py", line 1791, in dispatch_request
    self.raise_routing_exception(req)
  File "C:\ProgramData\Anaconda3\envs\BI-dashboard\lib\site-packages\flask\app.py", line 1774, in raise_routing_exception
    raise request.routing_exception
  File "C:\ProgramData\Anaconda3\envs\BI-dashboard\lib\site-packages\flask\ctx.py", line 336, in match_request
    self.url_adapter.match(return_rule=True)
  File "C:\ProgramData\Anaconda3\envs\BI-dashboard\lib\site-packages\werkzeug\routing.py", line 1581, in match
    raise NotFound()
werkzeug.exceptions.NotFound: 404 Not Found: The requested URL was not found on the server.  If you entered the URL manually please check your spelling and try again.
2018-10-30 10:19:22,226 - da-service - WARNING - 访问了未知路径: [error: 404 Not Found: The requested URL was not found on the server.  If you entered the URL manually please check your spelling and try again.]
Traceback (most recent call last):
  File "C:\ProgramData\Anaconda3\envs\BI-dashboard\lib\site-packages\flask\app.py", line 1813, in full_dispatch_request
    rv = self.dispatch_request()
  File "C:\ProgramData\Anaconda3\envs\BI-dashboard\lib\site-packages\flask\app.py", line 1799, in dispatch_request
    return self.view_functions[rule.endpoint](**req.view_args)
  File "C:\ProgramData\Anaconda3\envs\BI-dashboard\lib\site-packages\flask\helpers.py", line 976, in send_static_file
    cache_timeout=cache_timeout)
  File "C:\ProgramData\Anaconda3\envs\BI-dashboard\lib\site-packages\flask\helpers.py", line 709, in send_from_directory
    raise NotFound()
werkzeug.exceptions.NotFound: 404 Not Found: The requested URL was not found on the server.  If you entered the URL manually please check your spelling and try again.
2018-10-30 10:19:41,950 - da-service - WARNING - 访问了未知路径: [error: 404 Not Found: The requested URL was not found on the server.  If you entered the URL manually please check your spelling and try again.]
Traceback (most recent call last):
  File "C:\ProgramData\Anaconda3\envs\BI-dashboard\lib\site-packages\flask\app.py", line 1813, in full_dispatch_request
    rv = self.dispatch_request()
  File "C:\ProgramData\Anaconda3\envs\BI-dashboard\lib\site-packages\flask\app.py", line 1799, in dispatch_request
    return self.view_functions[rule.endpoint](**req.view_args)
  File "C:\ProgramData\Anaconda3\envs\BI-dashboard\lib\site-packages\flask\helpers.py", line 976, in send_static_file
    cache_timeout=cache_timeout)
  File "C:\ProgramData\Anaconda3\envs\BI-dashboard\lib\site-packages\flask\helpers.py", line 709, in send_from_directory
    raise NotFound()
werkzeug.exceptions.NotFound: 404 Not Found: The requested URL was not found on the server.  If you entered the URL manually please check your spelling and try again.
2018-10-30 10:19:52,965 - da-service - WARNING - 访问了未知路径: [error: 404 Not Found: The requested URL was not found on the server.  If you entered the URL manually please check your spelling and try again.]
Traceback (most recent call last):
  File "C:\ProgramData\Anaconda3\envs\BI-dashboard\lib\site-packages\flask\app.py", line 1813, in full_dispatch_request
    rv = self.dispatch_request()
  File "C:\ProgramData\Anaconda3\envs\BI-dashboard\lib\site-packages\flask\app.py", line 1791, in dispatch_request
    self.raise_routing_exception(req)
  File "C:\ProgramData\Anaconda3\envs\BI-dashboard\lib\site-packages\flask\app.py", line 1774, in raise_routing_exception
    raise request.routing_exception
  File "C:\ProgramData\Anaconda3\envs\BI-dashboard\lib\site-packages\flask\ctx.py", line 336, in match_request
    self.url_adapter.match(return_rule=True)
  File "C:\ProgramData\Anaconda3\envs\BI-dashboard\lib\site-packages\werkzeug\routing.py", line 1581, in match
    raise NotFound()
werkzeug.exceptions.NotFound: 404 Not Found: The requested URL was not found on the server.  If you entered the URL manually please check your spelling and try again.
2018-10-30 10:20:54,223 - da-service - WARNING - 访问了未知路径: [error: 404 Not Found: The requested URL was not found on the server.  If you entered the URL manually please check your spelling and try again.]
Traceback (most recent call last):
  File "C:\ProgramData\Anaconda3\envs\BI-dashboard\lib\site-packages\flask\app.py", line 1813, in full_dispatch_request
    rv = self.dispatch_request()
  File "C:\ProgramData\Anaconda3\envs\BI-dashboard\lib\site-packages\flask\app.py", line 1791, in dispatch_request
    self.raise_routing_exception(req)
  File "C:\ProgramData\Anaconda3\envs\BI-dashboard\lib\site-packages\flask\app.py", line 1774, in raise_routing_exception
    raise request.routing_exception
  File "C:\ProgramData\Anaconda3\envs\BI-dashboard\lib\site-packages\flask\ctx.py", line 336, in match_request
    self.url_adapter.match(return_rule=True)
  File "C:\ProgramData\Anaconda3\envs\BI-dashboard\lib\site-packages\werkzeug\routing.py", line 1581, in match
    raise NotFound()
werkzeug.exceptions.NotFound: 404 Not Found: The requested URL was not found on the server.  If you entered the URL manually please check your spelling and try again.
2018-10-30 10:20:54,270 - da-service - WARNING - 访问了未知路径: [error: 404 Not Found: The requested URL was not found on the server.  If you entered the URL manually please check your spelling and try again.]
Traceback (most recent call last):
  File "C:\ProgramData\Anaconda3\envs\BI-dashboard\lib\site-packages\flask\app.py", line 1813, in full_dispatch_request
    rv = self.dispatch_request()
  File "C:\ProgramData\Anaconda3\envs\BI-dashboard\lib\site-packages\flask\app.py", line 1791, in dispatch_request
    self.raise_routing_exception(req)
  File "C:\ProgramData\Anaconda3\envs\BI-dashboard\lib\site-packages\flask\app.py", line 1774, in raise_routing_exception
    raise request.routing_exception
  File "C:\ProgramData\Anaconda3\envs\BI-dashboard\lib\site-packages\flask\ctx.py", line 336, in match_request
    self.url_adapter.match(return_rule=True)
  File "C:\ProgramData\Anaconda3\envs\BI-dashboard\lib\site-packages\werkzeug\routing.py", line 1581, in match
    raise NotFound()
werkzeug.exceptions.NotFound: 404 Not Found: The requested URL was not found on the server.  If you entered the URL manually please check your spelling and try again.
2018-10-30 10:20:54,310 - da-service - WARNING - 访问了未知路径: [error: 404 Not Found: The requested URL was not found on the server.  If you entered the URL manually please check your spelling and try again.]
Traceback (most recent call last):
  File "C:\ProgramData\Anaconda3\envs\BI-dashboard\lib\site-packages\flask\app.py", line 1813, in full_dispatch_request
    rv = self.dispatch_request()
  File "C:\ProgramData\Anaconda3\envs\BI-dashboard\lib\site-packages\flask\app.py", line 1799, in dispatch_request
    return self.view_functions[rule.endpoint](**req.view_args)
  File "C:\ProgramData\Anaconda3\envs\BI-dashboard\lib\site-packages\flask\helpers.py", line 976, in send_static_file
    cache_timeout=cache_timeout)
  File "C:\ProgramData\Anaconda3\envs\BI-dashboard\lib\site-packages\flask\helpers.py", line 709, in send_from_directory
    raise NotFound()
werkzeug.exceptions.NotFound: 404 Not Found: The requested URL was not found on the server.  If you entered the URL manually please check your spelling and try again.
2018-10-30 10:21:54,868 - da-service - WARNING - 访问了未知路径: [error: 404 Not Found: The requested URL was not found on the server.  If you entered the URL manually please check your spelling and try again.]
Traceback (most recent call last):
  File "C:\ProgramData\Anaconda3\envs\BI-dashboard\lib\site-packages\flask\app.py", line 1813, in full_dispatch_request
    rv = self.dispatch_request()
  File "C:\ProgramData\Anaconda3\envs\BI-dashboard\lib\site-packages\flask\app.py", line 1791, in dispatch_request
    self.raise_routing_exception(req)
  File "C:\ProgramData\Anaconda3\envs\BI-dashboard\lib\site-packages\flask\app.py", line 1774, in raise_routing_exception
    raise request.routing_exception
  File "C:\ProgramData\Anaconda3\envs\BI-dashboard\lib\site-packages\flask\ctx.py", line 336, in match_request
    self.url_adapter.match(return_rule=True)
  File "C:\ProgramData\Anaconda3\envs\BI-dashboard\lib\site-packages\werkzeug\routing.py", line 1581, in match
    raise NotFound()
werkzeug.exceptions.NotFound: 404 Not Found: The requested URL was not found on the server.  If you entered the URL manually please check your spelling and try again.
2018-10-30 10:21:54,922 - da-service - WARNING - 访问了未知路径: [error: 404 Not Found: The requested URL was not found on the server.  If you entered the URL manually please check your spelling and try again.]
Traceback (most recent call last):
  File "C:\ProgramData\Anaconda3\envs\BI-dashboard\lib\site-packages\flask\app.py", line 1813, in full_dispatch_request
    rv = self.dispatch_request()
  File "C:\ProgramData\Anaconda3\envs\BI-dashboard\lib\site-packages\flask\app.py", line 1791, in dispatch_request
    self.raise_routing_exception(req)
  File "C:\ProgramData\Anaconda3\envs\BI-dashboard\lib\site-packages\flask\app.py", line 1774, in raise_routing_exception
    raise request.routing_exception
  File "C:\ProgramData\Anaconda3\envs\BI-dashboard\lib\site-packages\flask\ctx.py", line 336, in match_request
    self.url_adapter.match(return_rule=True)
  File "C:\ProgramData\Anaconda3\envs\BI-dashboard\lib\site-packages\werkzeug\routing.py", line 1581, in match
    raise NotFound()
werkzeug.exceptions.NotFound: 404 Not Found: The requested URL was not found on the server.  If you entered the URL manually please check your spelling and try again.
2018-10-30 10:21:55,012 - da-service - WARNING - 访问了未知路径: [error: 404 Not Found: The requested URL was not found on the server.  If you entered the URL manually please check your spelling and try again.]
Traceback (most recent call last):
  File "C:\ProgramData\Anaconda3\envs\BI-dashboard\lib\site-packages\flask\app.py", line 1813, in full_dispatch_request
    rv = self.dispatch_request()
  File "C:\ProgramData\Anaconda3\envs\BI-dashboard\lib\site-packages\flask\app.py", line 1799, in dispatch_request
    return self.view_functions[rule.endpoint](**req.view_args)
  File "C:\ProgramData\Anaconda3\envs\BI-dashboard\lib\site-packages\flask\helpers.py", line 976, in send_static_file
    cache_timeout=cache_timeout)
  File "C:\ProgramData\Anaconda3\envs\BI-dashboard\lib\site-packages\flask\helpers.py", line 709, in send_from_directory
    raise NotFound()
werkzeug.exceptions.NotFound: 404 Not Found: The requested URL was not found on the server.  If you entered the URL manually please check your spelling and try again.
2018-10-30 10:22:24,499 - da-service - WARNING - 访问了未知路径: [error: 404 Not Found: The requested URL was not found on the server.  If you entered the URL manually please check your spelling and try again.]
Traceback (most recent call last):
  File "C:\ProgramData\Anaconda3\envs\BI-dashboard\lib\site-packages\flask\app.py", line 1813, in full_dispatch_request
    rv = self.dispatch_request()
  File "C:\ProgramData\Anaconda3\envs\BI-dashboard\lib\site-packages\flask\app.py", line 1791, in dispatch_request
    self.raise_routing_exception(req)
  File "C:\ProgramData\Anaconda3\envs\BI-dashboard\lib\site-packages\flask\app.py", line 1774, in raise_routing_exception
    raise request.routing_exception
  File "C:\ProgramData\Anaconda3\envs\BI-dashboard\lib\site-packages\flask\ctx.py", line 336, in match_request
    self.url_adapter.match(return_rule=True)
  File "C:\ProgramData\Anaconda3\envs\BI-dashboard\lib\site-packages\werkzeug\routing.py", line 1581, in match
    raise NotFound()
werkzeug.exceptions.NotFound: 404 Not Found: The requested URL was not found on the server.  If you entered the URL manually please check your spelling and try again.
2018-10-30 10:22:24,598 - da-service - WARNING - 访问了未知路径: [error: 404 Not Found: The requested URL was not found on the server.  If you entered the URL manually please check your spelling and try again.]
Traceback (most recent call last):
  File "C:\ProgramData\Anaconda3\envs\BI-dashboard\lib\site-packages\flask\app.py", line 1813, in full_dispatch_request
    rv = self.dispatch_request()
  File "C:\ProgramData\Anaconda3\envs\BI-dashboard\lib\site-packages\flask\app.py", line 1791, in dispatch_request
    self.raise_routing_exception(req)
  File "C:\ProgramData\Anaconda3\envs\BI-dashboard\lib\site-packages\flask\app.py", line 1774, in raise_routing_exception
    raise request.routing_exception
  File "C:\ProgramData\Anaconda3\envs\BI-dashboard\lib\site-packages\flask\ctx.py", line 336, in match_request
    self.url_adapter.match(return_rule=True)
  File "C:\ProgramData\Anaconda3\envs\BI-dashboard\lib\site-packages\werkzeug\routing.py", line 1581, in match
    raise NotFound()
werkzeug.exceptions.NotFound: 404 Not Found: The requested URL was not found on the server.  If you entered the URL manually please check your spelling and try again.
